Workbook

Sheet 통합
BB1: (Updated) 2025-02-11
B2: 라오어 무한 매수법 | J2: 언이시트 | N2: 통합 v1.2
U3: (*중요*) 이 시트는 무한매수법 진행 과정에서 필요한 계산을 도와줄 목적으로 공유하는 것으로서, 종목 매수/매도를 추천하는 시트가 아님을 안내드립니다.
B5: 방법론 | D5: V1 | F5: https://cafe.naver.com/infinitebuying/1975 | U5: 진심으로 감사드립니다.
D6: V2 | F6: https://cafe.naver.com/infinitebuying/7398 | U6: 라오어님, 공간탐색자, 일신우일신, 긍정, 무파마, 진진진67, 경자원, 건강하고 아름다운 삶, 윌코이, 바바파파21, 낭만꿀벌, 나우리, 50세30억라오어짱, 라비에, 조용하게 살기, 플룻, 아름다운삶, 달과물, 쥰쥰, 전슬로, 노장황선홍, 경오일, bgsjdak, 콩나물, 아리차, 한신, 굿나잇, 일인지하만인지상, 핑크마카롱, 알로하, 킹배, 정국짱, 재우서맘, stumpandy, 로잔, 수아아빠요, YM, 유어리지, 유바라기0, 그린파파야향기, 원라이프, 연운채, 덩이둥이파, 도반, 슈미트2, 하은혜, 나는야워킹맘, 겨울의날개, 독립과자유, 지영마미, 지지탑, 메멘토모리, 짱뚱2, 주식부자Q, 앨스워드, 은퇴고고, 김도야 화성, 성가로이, 당연합죠, 스탠드업, 은퇴할껴, 하하이브, 호학심사, 럽지안, 어린왕자의 장미꽃, 타요, money Ae, wait38, 졍졍짱, 맑은샘소리, 나도한다, 우리존재화이팅, 우유비누, 또순멍멍, 무매법만세, 루틴, NAIL말고지금, 부링링, hwaddassa, 승재아빠, 모두의엄, 고요, 좋은씨앗, 미스타팍, 엠씨미니, 아이니스타, 뽀대, 말리꽃, 백전, 무쏘의뿔, 집짓는건축가, 샤모, 신건축사, 사자, sink28, 나나로로, chAii, 찐윤여사, 심상사성1, 멜킴, 마타리이, 나무꾼12, diplo, 큐사랑, 블랙스완(빈나나), 다가천, 욘욘, wish, 레비트라, HY, 리비온, 아하라, 아라코코, 해뜰, 혀니즈, 블라썸, 풀소유, 무매머쒼, 공간, 상선약수09, 테니스홀릭, impro, 굿나잇, 보담, 251, 찬이둥이맘, 마라샹궈, 벨린느, 날자, 날다람쥐, 보조개, kathy, 오크스멜, 쫑쫑마, 피츄, 제니 맘, 옥타비아, 소다미, 조향풍, 6학년무린이, 켐일렉, 호야파, Snaker, 벼리, 꼬꼬날개, 손만대면플러스, 잡다지식, 또록빛깔, 주띵공주, 사람22, 조아조아랑, 리드앤드링크, 해피스마일, 하라는대로만, 시리아이, 헤드핑, 얼룩쏘, Plokmz, ezmagic, Justina, 더블샷에스프레소, 빨간토마토마, 에세푸릴, 반성하자, 리플리, 시너지7, 두니봉이, 서울에, 트무, 아나킨843, 룡나우지뉴, 엄마는공부중, 토르, snow0, Blackcoat, 스마트개미, 하항, 한번해볼까, 김수경, 마냥, my0727, 겨울잠잠, 파파, 맹아줄기, 즐거운 배움, 푸른하늘66, 예주시해, 호키포키, 10월의마지막날, 좋은아침, 현재즐김777, 성우맘, 버즈, 트립, VIN VIN, 바다로다이빙, kalabaw, 긍정에너지, 주띵공주, TLP 올인, 당근당근v, 나나별, 무매봇, 마음부자, 엠지, 나나언니, 쭌군파더, 버기, 주띵공주, 단아다나, 그릇키우기, 개천절2021, 레이본, 재혁마이, 물방울, 페가술스, 초보투자01, 젖어들기, 쇠똔구리, 환환, 모모난나, 잘나가는 종신씨, 쥄, 언젠가, 아나킨843, 워킹맘이과장, 멋진재진, 오실로, 성우맘, 둘리아빠, 바그스2022, 마리주니, 랜드마크강, 알로하, grain, 밥밥이, 스카이워커, 마리주니, Kathy, 별이 보이는 다락방, 뮬리, 이름모를어느분, Ibu Mia, 워킹맘이과장, 늘보의 하루, 최고야, 애느, 백전, borabom, 10년후50억, 엠지, 스피넬, 품격있는부자, 꽃너미, 엠지, 워킹맘이과장, 호미337, 하얀수선화, 희망108, ul4, 사운드시티, 민트v, 위드라니, 지니PT, 무한수익자, 워킹맘이과장, 꽃너미, 스피넬, 다카라, 로하, 앵두나무, 민둥산거북이, 슈바빙, 그릇키우기, 헤드핑, 강수니, 로하, kusk1961, hereNnow, 한걸음, 바그스2022, 치우천황, 랜드마크강, 해피스마일, 독립과 자유, 봄바람42, 뽀또, 밤호박, 공간탐색자, 딱조아, 쿼드러플5, 젖어들기, 벚꽃휘날리며, borabom, chrishan25, 영심, 쭈니행복, 로하, 뇽민수, 호미337, 지혜와 용기, 파랑새1902, 진공묘유무위이화, 멘탈키우기, 엠지, 로하, 지구인ㅁ9203, 쥄, 사운드시티, 마냥, 방가워욧, 워킹맘이과장, Justina, 드래곤에그, 신건축사, 도사브로, 날마다 좋은, 졸꾸, 엠지, 낭만꿀벌, 엄마는공부중, 엠씨미니, 윤쥬킴, 장판집고양이, 의용증나7, 레드야앙, 워킹맘이과장, 젖어들기, 졸꾸, 반말하지마세요, 젖어들기, 흔한X트라, 엠지, 워킹맘이과장, 얼룩쏘, 젖어들기, 쥄, 뽀또, 로하, 가다오다서, 젖어들기, 엠지, 하얀수선화, 달토끼, 바그스2022, 벚꽃휘날리며, 젖어들기, 알로하, 젖어들기, 워킹맘이과장, 징기, 졸꾸
D7: V2.1 | F7: https://cafe.naver.com/infinitebuying/21554
D8: V2.2 | F8: https://cafe.naver.com/infinitebuying/48744
D9: V3.0 | F9: https://cafe.naver.com/infinitebuying/59826
B12: ★ 모든 시트 참조 ★
B13: 1. 파란색 계열 부분만 직접 입력하시면 됩니다. 2. 그 외 부분의 수정을 원하시면 경고문구가 나타났을 때, '확인'을 누르신 후 수정하시면 됩니다. 3. 매도 수수료 입력 후 %가 제대로 붙어있는지 확인 해주세요. 4. 사용 중 문제가 있을 시 댓글로 문의 바랍니다.
B23: <기본 1> 시드 현황 | P23: <추매 1> 시드 현황 | AD23: <V3&IBS_1> 시드 현황
B25: 원금 합계 | E25: ='기본1'!AV7 | I25: 평가금 | K25: ='기본1'!BB7 | P25: 원금 합계 | S25: ='추매1'!AV7 | W25: 평가금 | Y25: ='추매1'!BB7 | AD25: 원금 합계 | AG25: ='V3 1'!AY7 | AK25: 평가금 | AM25: ='V3 1'!BE7
I26: 손익 | K26: ='기본1'!BB8 | W26: 손익 | Y26: ='추매1'!BB8 | AK26: 손익 | AM26: ='V3 1'!BE8
B27: 매입 금액 | E27: ='기본1'!AV9 | I27: 수익률 | K27: ↔투입 | M27: ='기본1'!BD9 -> 0 | P27: 매입 금액 | S27: ='추매1'!AV9 | W27: 수익률 | Y27: ↔투입 | AA27: ='추매1'!BD9 -> 0 | AD27: 매입 금액 | AG27: ='V3 1'!AY9 | AK27: 수익률 | AM27: ↔투입 | AO27: ='V3 1'!BG9 -> 0
B28: 남은 원금 | E28: ='기본1'!AV10 | K28: =IFERROR(__xludf.DUMMYFUNCTION("'기본1'!BB10"),"") | P28: 남은 원금 | S28: ='추매1'!AV10 | Y28: =IFERROR(__xludf.DUMMYFUNCTION("'추매1'!BB10"),"") | AD28: 남은 원금 | AG28: ='V3 1'!AY10 | AM28: =IFERROR(__xludf.DUMMYFUNCTION("'V3 1'!BE10"),"") | AS28: 통합 시드 현황
B29: 소진율 | E29: ='기본1'!AV11 | P29: 소진율 | S29: ='추매1'!AV11 | AD29: 소진율 | AG29: ='V3 1'!AY11
B30: ='기본1'!AS12 | P30: ='추매1'!AS12 | AD30: ='V3 1'!AV12 | AS30: 원금 합계 | AV30: =IF(E25+E38+S25+S38+AG25+AG38=0,"",E25+E38+S25+S38+AG25+AG38) | AZ30: 평가금 | BB30: =IF(K25+K38+Y25+Y38+AM25+AM38=0,"",K25+K38+Y25+Y38+AM25+AM38)
B31: 1일 매입액 | E31: ='기본1'!AV13 -> 0 | K31: ↔원금 | M31: ='기본1'!BD13 -> 0 | P31: 1일 매입액 | S31: ='추매1'!AV13 -> 0 | Y31: ↔원금 | AA31: ='추매1'!BD13 -> 0 | AD31: 1일 매입액 | AG31: ='V3 1'!AY13 -> 0 | AM31: ↔원금 | AO31: ='V3 1'!BG13 -> 0 | AZ31: 손익 | BB31: =IF(K26+K39+Y26+Y39+AM26+AM39=0,"",K26+K39+Y26+Y39+AM26+AM39)
B32: 매도수수료 | E32: ='기본1'!AV14 -> 0.0002 | K32: =IFERROR(__xludf.DUMMYFUNCTION("'기본1'!BB14"),"") | P32: 매도수수료 | S32: ='추매1'!AV14 -> 0.0002 | Y32: =IFERROR(__xludf.DUMMYFUNCTION("'추매1'!BB14"),"") | AD32: 매도수수료 | AG32: ='V3 1'!AY14 -> 0.0002 | AM32: =IFERROR(__xludf.DUMMYFUNCTION("'V3 1'!BE14"),"") | AS32: 매입 금액 | AV32: =IF(E27+E40+S27+S40+AG27+AG40=0,"",E27+E40+S27+S40+AG27+AG40) | AZ32: 수익률 | BB32: ↔투입 | BD32: =IFERROR(BB31/AV32,0) -> 0
B33: 증액가능 | E33: ='기본1'!AV15 -> 0 | P33: 증액가능 | S33: ='추매1'!AV15 -> 0 | AS33: 남은 원금 | AV33: =IF(E28+E41+S28+S41+AG28+AG41=0,"",E28+E41+S28+S41+AG28+AG41) | BB33: =IFERROR(__xludf.DUMMYFUNCTION("IFERROR(SPARKLINE(BD32,{""charttype"", ""column"";""color"",""FF0000""; ""negcolor"", ""0000FF""; ""ymin"", -0.3 ; ""ymax"", +0.2 ;""axis"",true ; ""axiscolor"",""000000""}),"""")"),"")
AS34: 소진율 | AV34: =IF(AV33="","",AV32/AV30)
AS35: =IFERROR(__xludf.DUMMYFUNCTION("IFERROR(IF(AV34>=0.5,SPARKLINE(AV34,{""charttype"",""bar"";""max"",1;""color1"",""FFB400""}),SPARKLINE(AV34,{""charttype"",""bar"";""max"",1;""color1"",""80E12A""})),"""")"),"")
B36: <기본 2> 시드 현황 | P36: <추매 2> 시드 현황 | AD36: <V3&IBS_2> 시드 현황 | AS36: 1일 매입액 | AV36: =E31+E44+S31+S44+AG31+AG44 -> 0 | BB36: ↔원금 | BD36: =IFERROR(BB31/AV30,0) -> 0
BB37: =IFERROR(__xludf.DUMMYFUNCTION("IFERROR(SPARKLINE(BD36,{""charttype"", ""column"";""color"",""FF0000""; ""negcolor"", ""0000FF""; ""ymin"", -0.3 ; ""ymax"", +0.2 ;""axis"",true ; ""axiscolor"",""000000""}),"""")"),"")
B38: 원금 합계 | E38: ='기본2'!AV7 | I38: 평가금 | K38: ='기본2'!BB7 | P38: 원금 합계 | S38: ='추매2'!AV7 | W38: 평가금 | Y38: ='추매2'!BB7 | AD38: 원금 합계 | AG38: ='V3&IBS 2'!AY7 | AK38: 평가금 | AM38: ='V3&IBS 2'!BE7
I39: 손익 | K39: ='기본2'!BB8 | W39: 손익 | Y39: ='추매2'!BB8 | AK39: 손익 | AM39: ='V3&IBS 2'!BE8
B40: 매입 금액 | E40: ='기본2'!AV9 | I40: 수익률 | K40: ↔투입 | M40: ='기본2'!BD9 -> 0 | P40: 매입 금액 | S40: ='추매2'!AV9 | W40: 수익률 | Y40: ↔투입 | AA40: ='추매2'!BD9 -> 0 | AD40: 매입 금액 | AG40: ='V3&IBS 2'!AY9 | AK40: 수익률 | AM40: ↔투입 | AO40: ='V3&IBS 2'!BG9 -> 0
B41: 남은 원금 | E41: ='기본2'!AV10 | K41: =IFERROR(__xludf.DUMMYFUNCTION("'기본2'!BB10"),"") | P41: 남은 원금 | S41: ='추매2'!AV10 | Y41: =IFERROR(__xludf.DUMMYFUNCTION("'추매2'!BB10"),"") | AD41: 남은 원금 | AG41: ='V3&IBS 2'!AY10 | AM41: =IFERROR(__xludf.DUMMYFUNCTION("'V3&IBS 2'!BE10"),"")
B42: 소진율 | E42: ='기본2'!AV11 | P42: 소진율 | S42: ='추매2'!AV11 | AD42: 소진율 | AG42: ='V3&IBS 2'!AY11
B43: ='기본2'!AS12 | P43: ='추매2'!AS12 | AD43: ='V3&IBS 2'!AV12
B44: 1일 매입액 | E44: ='기본2'!AV13 -> 0 | K44: ↔원금 | M44: ='기본2'!BD13 -> 0 | P44: 1일 매입액 | S44: ='추매2'!AV13 -> 0 | Y44: ↔원금 | AA44: ='추매2'!BD13 -> 0 | AD44: 1일 매입액 | AG44: ='V3&IBS 2'!AY13 -> 0 | AM44: ↔원금 | AO44: ='V3&IBS 2'!BG13 -> 0
B45: 매도수수료 | E45: ='기본2'!AV14 -> 0.0002 | K45: =IFERROR(__xludf.DUMMYFUNCTION("'기본2'!BB14"),"") | P45: 매도수수료 | S45: ='추매2'!AV14 -> 0.0002 | Y45: =IFERROR(__xludf.DUMMYFUNCTION("'추매2'!BB14"),"") | AD45: 매도수수료 | AG45: ='V3&IBS 2'!AY14 -> 0.0002 | AM45: =IFERROR(__xludf.DUMMYFUNCTION("'V3&IBS 2'!BE14"),"")
B46: 증액가능 | E46: ='기본2'!AV15 -> 0 | P46: 증액가능 | S46: ='추매2'!AV15 -> 0
B50: 종목 DATA | AC50: 최소원금 계산기 | AI50: 분할 수
C51: Ticker | E51: 현재가 | H51: 추세(10) | K51: 전일대비 | N51: 등락률 | Q51: 기준RSI | S51: RSI | U51: 차이 | W51: 괴리율 | Y51: 진입 | AA51: ※ LOC | AC51: 1회 | AE51: 필요 원금 | AI51: 40
B52: 1 | C52: SOXL | E52: =IFERROR(__xludf.DUMMYFUNCTION("IFERROR(GOOGLEFINANCE(C52,""price""),INDEX(importhtml(""https://finviz.com/screener.ashx?v=170&t=""&C52&""&ar=180"",""table"",12),2,11))"),136.81) -> 136.81 | H52: =IFERROR(__xludf.DUMMYFUNCTION("IF($H$51=""추세(20)"",IFERROR(SPARKLINE(GOOGLEFINANCE(C52,""price"",TODAY()-26,TODAY(),1)),""Updating..""),IFERROR(SPARKLINE(GOOGLEFINANCE(C52,""price"",TODAY()-12,TODAY(),1)),""Updating..""))"),"") | K52: =IFERROR(__xludf.DUMMYFUNCTION("IFERROR(GOOGLEFINANCE(C52,""change""),"""")"),1.34) -> 1.34 | N52: =IFERROR(__xludf.DUMMYFUNCTION("IFERROR(GOOGLEFINANCE(C52,""changepct"")/100,"""")"),0.009899999999999999) -> 0.0099 | Q52: 65 | S52: =IFERROR(__xludf.DUMMYFUNCTION("IFERROR(INDEX(importhtml(""https://finviz.com/screener.ashx?v=170&t=""&C52&""&ar=180"",""table"",12),2,10),""Load.."")"),39.65) -> 39.65 | U52: =IFERROR(Q52-S52,"Load..") -> 25.35 | W52: =IFERROR(U52/Q52,"Load..") -> 0.39 | Y52: =IF(S52="Loading","Loading",IF(Q52>S52,"YES","NO")) -> YES | AC52: 2 | AE52: =IF(AC52="","",E52*1.15*AC52*$AI$51) -> 12586.52
B53: 2 | C53: BULZ | E53: =IFERROR(__xludf.DUMMYFUNCTION("IFERROR(GOOGLEFINANCE(C53,""price""),INDEX(importhtml(""https://finviz.com/screener.ashx?v=170&t=""&C53&""&ar=180"",""table"",12),2,11))"),32.67) -> 32.67 | H53: =IFERROR(__xludf.DUMMYFUNCTION("IF($H$51=""추세(20)"",IFERROR(SPARKLINE(GOOGLEFINANCE(C53,""price"",TODAY()-26,TODAY(),1)),""Updating..""),IFERROR(SPARKLINE(GOOGLEFINANCE(C53,""price"",TODAY()-12,TODAY(),1)),""Updating..""))"),"") | K53: =IFERROR(__xludf.DUMMYFUNCTION("IFERROR(GOOGLEFINANCE(C53,""change""),"""")"),0.37) -> 0.37 | N53: =IFERROR(__xludf.DUMMYFUNCTION("IFERROR(GOOGLEFINANCE(C53,""changepct"")/100,"""")"),0.0115) -> 0.0115 | Q53: 65 | S53: =IFERROR(__xludf.DUMMYFUNCTION("IFERROR(INDEX(importhtml(""https://finviz.com/screener.ashx?v=170&t=""&C53&""&ar=180"",""table"",12),2,10),""Load.."")"),39.48) -> 39.48 | U53: =IFERROR(Q53-S53,"Load..") -> 25.52 | W53: =IFERROR(U53/Q53,"Load..") -> 0.39261538 | Y53: =IF(S53="Loading","Loading",IF(Q53>S53,"YES","NO")) -> YES | AC53: 2 | AE53: =IF(AC53="","",E53*1.15*AC53*$AI$51) -> 3005.64
B54: 3 | C54: TQQQ | E54: =IFERROR(__xludf.DUMMYFUNCTION("IFERROR(GOOGLEFINANCE(C54,""price""),INDEX(importhtml(""https://finviz.com/screener.ashx?v=170&t=""&C54&""&ar=180"",""table"",12),2,11))"),67.65) -> 67.65 | H54: =IFERROR(__xludf.DUMMYFUNCTION("IF($H$51=""추세(20)"",IFERROR(SPARKLINE(GOOGLEFINANCE(C54,""price"",TODAY()-26,TODAY(),1)),""Updating..""),IFERROR(SPARKLINE(GOOGLEFINANCE(C54,""price"",TODAY()-12,TODAY(),1)),""Updating..""))"),"") | K54: =IFERROR(__xludf.DUMMYFUNCTION("IFERROR(GOOGLEFINANCE(C54,""change""),"""")"),0.12) -> 0.12 | N54: =IFERROR(__xludf.DUMMYFUNCTION("IFERROR(GOOGLEFINANCE(C54,""changepct"")/100,"""")"),0.0018) -> 0.0018 | Q54: 60 | S54: =IFERROR(__xludf.DUMMYFUNCTION("IFERROR(INDEX(importhtml(""https://finviz.com/screener.ashx?v=170&t=""&C54&""&ar=180"",""table"",12),2,10),""Load.."")"),40.95) -> 40.95 | U54: =IFERROR(Q54-S54,"Load..") -> 19.05 | W54: =IFERROR(U54/Q54,"Load..") -> 0.3175 | Y54: =IF(S54="Loading","Loading",IF(Q54>S54,"YES","NO")) -> YES | AC54: 2 | AE54: =IF(AC54="","",E54*1.15*AC54*$AI$51) -> 6223.8
B55: 4 | C55: TECL | E55: =IFERROR(__xludf.DUMMYFUNCTION("IFERROR(GOOGLEFINANCE(C55,""price""),INDEX(importhtml(""https://finviz.com/screener.ashx?v=170&t=""&C55&""&ar=180"",""table"",12),2,11))"),177.86) -> 177.86 | H55: =IFERROR(__xludf.DUMMYFUNCTION("IF($H$51=""추세(20)"",IFERROR(SPARKLINE(GOOGLEFINANCE(C55,""price"",TODAY()-26,TODAY(),1)),""Updating..""),IFERROR(SPARKLINE(GOOGLEFINANCE(C55,""price"",TODAY()-12,TODAY(),1)),""Updating..""))"),"") | K55: =IFERROR(__xludf.DUMMYFUNCTION("IFERROR(GOOGLEFINANCE(C55,""change""),"""")"),0.21) -> 0.21 | N55: =IFERROR(__xludf.DUMMYFUNCTION("IFERROR(GOOGLEFINANCE(C55,""changepct"")/100,"""")"),0.0012) -> 0.0012 | Q55: 60 | S55: =IFERROR(__xludf.DUMMYFUNCTION("IFERROR(INDEX(importhtml(""https://finviz.com/screener.ashx?v=170&t=""&C55&""&ar=180"",""table"",12),2,10),""Load.."")"),41.24) -> 41.24 | U55: =IFERROR(Q55-S55,"Load..") -> 18.76 | W55: =IFERROR(U55/Q55,"Load..") -> 0.31266667 | Y55: =IF(S55="Loading","Loading",IF(Q55>S55,"YES","NO")) -> YES | AC55: 2 | AE55: =IF(AC55="","",E55*1.15*AC55*$AI$51) -> 16363.12
B56: 5 | C56: WEBL | E56: =IFERROR(__xludf.DUMMYFUNCTION("IFERROR(GOOGLEFINANCE(C56,""price""),INDEX(importhtml(""https://finviz.com/screener.ashx?v=170&t=""&C56&""&ar=180"",""table"",12),2,11))"),24.37) -> 24.37 | H56: =IFERROR(__xludf.DUMMYFUNCTION("IF($H$51=""추세(20)"",IFERROR(SPARKLINE(GOOGLEFINANCE(C56,""price"",TODAY()-26,TODAY(),1)),""Updating..""),IFERROR(SPARKLINE(GOOGLEFINANCE(C56,""price"",TODAY()-12,TODAY(),1)),""Updating..""))"),"") | K56: =IFERROR(__xludf.DUMMYFUNCTION("IFERROR(GOOGLEFINANCE(C56,""change""),"""")"),0.16) -> 0.16 | N56: =IFERROR(__xludf.DUMMYFUNCTION("IFERROR(GOOGLEFINANCE(C56,""changepct"")/100,"""")"),0.0066) -> 0.0066 | Q56: 60 | S56: =IFERROR(__xludf.DUMMYFUNCTION("IFERROR(INDEX(importhtml(""https://finviz.com/screener.ashx?v=170&t=""&C56&""&ar=180"",""table"",12),2,10),""Load.."")"),49.15) -> 49.15 | U56: =IFERROR(Q56-S56,"Load..") -> 10.85 | W56: =IFERROR(U56/Q56,"Load..") -> 0.18083333 | Y56: =IF(S56="Loading","Loading",IF(Q56>S56,"YES","NO")) -> YES | AA56: ※ | AC56: 2 | AE56: =IF(AC56="","",E56*1.15*AC56*$AI$51) -> 2242.04
...

Sheet V3 1
A1: v
B2: 라오어 무한 매수법 | J2: 언이시트 | N2: V3 1 | BT2: V3 | CB2: IBS
BP3: 1 | BR3: 매수 | BT3: 평단 | BW3: =IF(BY3>BY5,"",IF(G19<0.5,IF(AF7="","",IF(BY4<BY5,ROUNDDOWN(S7/BY3,0)-BW4,ROUNDDOWN(S7/BY3,0)-BW5)),"")) | BY3: =IF(AF7="","",AF7) | CB3: 평단 | CG3: =IF(AF7="","",AF7)
BT4: =IF(J19="",N7,(N7-J19*N7/(0.5*P7))) -> 0.15 | BW4: =IF(AC7="","",IF(BY4>BY5,"",IF(G19<0.5,ROUNDDOWN(S7/2/BY4,0),IF(E23<S7,ROUNDDOWN(E23/BY4,0),ROUNDDOWN(S7/BY4,0))))) | BY4: =IF(AF7="","",AF7*(1+BT4)) | CB4: =IF(J19="",N7,(N7-J19*N7/(0.5*P7))) -> 0.15 | CE4: =IF(AC7="","",IF(CG4>CG5,"",IF(E23<S7,ROUNDDOWN(E23/CG4,0),ROUNDDOWN(S7/CG4,0)))) | CG4: =IF(AF7="","",AF7*(1+CB4))
C5: 첫 매수 시 기록 | AC5: 매일 기록 | AI5: 종목 정보 | AV5: 시드 현황 | BT5: 큰수 | BW5: =IF(AC7="","",IF(BY4<BY5,"",IF(E23<S7,ROUNDDOWN(E23/BY5,0),IF(BY3>BY5,ROUNDDOWN(S7/BY5,0),ROUNDDOWN(S7/2/BY5,0))))) | BY5: =IF(AF7="","",AK7*(1+BJ16)) | CB5: 큰수 | CE5: =IF(AC7="","",IF(CG4<CG5,"",IF(E23<S7,ROUNDDOWN(E23/CG5,0),ROUNDDOWN(S7/CG5,0)))) | CG5: =IF(AF7="","",AK7*(1+BJ16))
C6: 종목 | E6: 매수법 | G6: 시작원금 | J6: ( ) 복리 | N6: 매도 | P6: 분할 | R6: 매수금 | U6: 매수량 | W6: 매수시작일 | Z6: 최초매입가 | AC6: 잔고수량 | AF6: 평단가 | AI6: RSI | AK6: 현재가 | AM6: =H101 -> 추세(10) | AP6: 전일대비 | AS6: 등락률 | BR6: 매도 | BT6: =IF(J19="","",(N7-J19*N7/(0.5*P7))) | BW6: =IF(AC7="","",ROUND(AC7/4,0)) | BY6: =IF(AF7="","",AF7*(1+$AY$14+BT6)) | CB6: =IF(J19="","",(N7-J19*N7/(0.5*P7))) | CE6: =IF(AC7="","",IF(ROUND(AC7/J19,0)>AC7,AC7,ROUND(AC7/J19,0))) | CG6: =IF(AF7="","",AF7*(1+$AY$14+CB6))
B7: 1 | E7: V3.0 | J7: 반 | K7: =IF(J7="완",IF(L72=0,"",G7+L72),IF(J7="반",IF(L72>0,G7+(L72/2),IF(L72=0,"",G7+L72)),"")) | N7: 0.15 | P7: 20 | R7: FALSE | S7: =IF(G7="","",IF(R7=TRUE,IF(K7="",G7/P7,K7/P7),IF(K7-G7>0,K7/P7,G7/P7))) | U7: =IFERROR(IF(G7="","",ROUNDDOWN(S7/AK7,0)),"") | AI7: =IF(C7="","",VLOOKUP(C7,$C$102:$T$106,17,FALSE)) | AK7: =IF(C7="","",VLOOKUP(C7,$C$102:$T$106,3,FALSE)) | AM7: =IF(C7="","",VLOOKUP(C7,$C$102:$T$106,6,FALSE)) | AP7: =IF(C7="","",VLOOKUP(C7,$C$102:$T$106,9,FALSE)) | AS7: =IF(C7="","",VLOOKUP(C7,$C$102:$T$106,12,FALSE)) | AV7: 원금 합계 | AY7: =IF(SUM(G7:I16)=0,"",SUM(G7:I16)) | BC7: 평가금 | BE7: =IF(AY9="","",E21+O21+Y21+AI21+AS21+E42+O42+Y42+AI42+AS42)
B8: 2 | E8: V3.0 | J8: 반 | K8: =IF(J8="완",IF(Z72=0,"",G8+Z72),IF(J8="반",IF(Z72>0,G8+(Z72/2),IF(Z72=0,"",G8+Z72)),"")) | N8: 0.15 | P8: 20 | R8: FALSE | S8: =IF(G8="","",IF(R8=TRUE,IF(K8="",G8/P8,K8/P8),IF(K8-G8>0,K8/P8,G8/P8))) | U8: =IFERROR(IF(G8="","",ROUNDDOWN(S8/AK8,0)),"") | AI8: =IF(C8="","",VLOOKUP(C8,$C$102:$T$106,17,FALSE)) | AK8: =IF(C8="","",VLOOKUP(C8,$C$102:$T$106,3,FALSE)) | AM8: =IF(C8="","",VLOOKUP(C8,$C$102:$T$106,6,FALSE)) | AP8: =IF(C8="","",VLOOKUP(C8,$C$102:$T$106,9,FALSE)) | AS8: =IF(C8="","",VLOOKUP(C8,$C$102:$T$106,12,FALSE)) | BC8: 손익 | BE8: =IF(BE7="","",BE7-AY9) | BT8: =$N$7 -> 0.15 | BW8: =IF(AC7="","",AC7-BW6) | BY8: =IF(AF7="","",AF7*(1+N7+$AY$14)) | CB8: =$N$7 -> 0.15 | CE8: =IF(AC7="","",AC7-CE6) | CG8: =IF(AF7="","",AF7*(1+N7+$AY$14))
B9: 3 | E9: V3.0 | J9: 반 | K9: =IF(J9="완",IF(AN72=0,"",G9+AN72),IF(J9="반",IF(AN72>0,G9+(AN72/2),IF(AN72=0,"",G9+AN72)),"")) | N9: 0.15 | P9: 20 | R9: FALSE | S9: =IF(G9="","",IF(R9=TRUE,IF(K9="",G9/P9,K9/P9),IF(K9-G9>0,K9/P9,G9/P9))) | U9: =IFERROR(IF(G9="","",ROUNDDOWN(S9/AK9,0)),"") | AI9: =IF(C9="","",VLOOKUP(C9,$C$102:$T$106,17,FALSE)) | AK9: =IF(C9="","",VLOOKUP(C9,$C$102:$T$106,3,FALSE)) | AM9: =IF(C9="","",VLOOKUP(C9,$C$102:$T$106,6,FALSE)) | AP9: =IF(C9="","",VLOOKUP(C9,$C$102:$T$106,9,FALSE)) | AS9: =IF(C9="","",VLOOKUP(C9,$C$102:$T$106,12,FALSE)) | AV9: 매입 금액 | AY9: =IF(AY7="","",E20+O20+Y20+AI20+AS20+E41+O41+Y41+AI41+AS41) | BC9: 수익률 | BE9: ↔투입 | BG9: =IFERROR(BE8/AY9,0) -> 0 | BP9: 2 | BR9: 매수 | BT9: 평단 | BW9: =IF(BY9>BY11,"",IF(Q19<0.5,IF(AF8="","",IF(BY10<BY11,ROUNDDOWN(S8/BY9,0)-BW10,ROUNDDOWN(S8/BY9,0)-BW11)),"")) | BY9: =IF(AF8="","",AF8) | CB9: 평단 | CG9: =IF(AF8="","",AF8)
B10: 4 | E10: V3.0 | J10: 반 | K10: =IF(J10="완",IF(BB72=0,"",G10+BB72),IF(J10="반",IF(BB72>0,G10+(BB72/2),IF(BB72=0,"",G10+BB72)),"")) | N10: 0.15 | P10: 20 | R10: FALSE | S10: =IF(G10="","",IF(R10=TRUE,IF(K10="",G10/P10,K10/P10),IF(K10-G10>0,K10/P10,G10/P10))) | U10: =IFERROR(IF(G10="","",ROUNDDOWN(S10/AK10,0)),"") | AI10: =IF(C10="","",VLOOKUP(C10,$C$102:$T$106,17,FALSE)) | AK10: =IF(C10="","",VLOOKUP(C10,$C$102:$T$106,3,FALSE)) | AM10: =IF(C10="","",VLOOKUP(C10,$C$102:$T$106,6,FALSE)) | AP10: =IF(C10="","",VLOOKUP(C10,$C$102:$T$106,9,FALSE)) | AS10: =IF(C10="","",VLOOKUP(C10,$C$102:$T$106,12,FALSE)) | AV10: 남은 원금 | AY10: =IF(AY7="","",AY7-AY9) | BE10: =IFERROR(__xludf.DUMMYFUNCTION("IFERROR(SPARKLINE(BG9,{""charttype"", ""column"";""color"",""FF0000""; ""negcolor"", ""0000FF""; ""ymin"", -0.3 ; ""ymax"", +0.2 ;""axis"",true ; ""axiscolor"",""000000""}),"""")"),"") | BT10: =IF(T19="",N8,(N8-T19*N8/(0.5*P8))) -> 0.15 | BW10: =IF(AC8="","",IF(BY10>BY11,"",IF(Q19<0.5,ROUNDDOWN(S8/2/BY10,0),IF(O23<S8,ROUNDDOWN(O23/BY10,0),ROUNDDOWN(S8/BY10,0))))) | BY10: =IF(AF8="","",AF8*(1+BT10)) | CB10: =IF(T19="",N8,(N8-T19*N8/(0.5*P8))) -> 0.15 | CE10: =IF(AC8="","",IF(CG10>CG11,"",IF(O23<S8,ROUNDDOWN(O23/CG10,0),ROUNDDOWN(S8/CG10,0)))) | CG10: =IF(AF8="","",AF8*(1+CB10))
B11: 5 | E11: V3.0 | J11: 반 | K11: =IF(J11="완",IF(L85=0,"",G11+L85),IF(J11="반",IF(L85>0,G11+(L85/2),IF(L85=0,"",G11+L85)),"")) | N11: 0.15 | P11: 20 | R11: FALSE | S11: =IF(G11="","",IF(R11=TRUE,IF(K11="",G11/P11,K11/P11),IF(K11-G11>0,K11/P11,G11/P11))) | U11: =IFERROR(IF(G11="","",ROUNDDOWN(S11/AK11,0)),"") | AI11: =IF(C11="","",VLOOKUP(C11,$C$102:$T$106,17,FALSE)) | AK11: =IF(C11="","",VLOOKUP(C11,$C$102:$T$106,3,FALSE)) | AM11: =IF(C11="","",VLOOKUP(C11,$C$102:$T$106,6,FALSE)) | AP11: =IF(C11="","",VLOOKUP(C11,$C$102:$T$106,9,FALSE)) | AS11: =IF(C11="","",VLOOKUP(C11,$C$102:$T$106,12,FALSE)) | AV11: 소진율 | AY11: =IF(AY10="","",AY9/AY7) | BT11: 큰수 | BW11: =IF(AC8="","",IF(BY10<BY11,"",IF(O23<S8,ROUNDDOWN(O23/BY11,0),IF(BY9>BY11,ROUNDDOWN(S8/BY11,0),ROUNDDOWN(S8/2/BY11,0))))) | BY11: =IF(AF8="","",AK8*(1+BJ16)) | CB11: 큰수 | CE11: =IF(AC8="","",IF(CG10<CG11,"",IF(O23<S8,ROUNDDOWN(O23/CG11,0),ROUNDDOWN(S8/CG11,0)))) | CG11: =IF(AF8="","",AK8*(1+BJ16))
B12: 6 | E12: V3.0 | J12: 반 | K12: =IF(J12="완",IF(Z85=0,"",G12+Z85),IF(J12="반",IF(Z85>0,G12+(Z85/2),IF(Z85=0,"",G12+Z85)),"")) | N12: 0.15 | P12: 20 | R12: FALSE | S12: =IF(G12="","",IF(R12=TRUE,IF(K12="",G12/P12,K12/P12),IF(K12-G12>0,K12/P12,G12/P12))) | U12: =IFERROR(IF(G12="","",ROUNDDOWN(S12/AK12,0)),"") | AI12: =IF(C12="","",VLOOKUP(C12,$C$102:$T$106,17,FALSE)) | AK12: =IF(C12="","",VLOOKUP(C12,$C$102:$T$106,3,FALSE)) | AM12: =IF(C12="","",VLOOKUP(C12,$C$102:$T$106,6,FALSE)) | AP12: =IF(C12="","",VLOOKUP(C12,$C$102:$T$106,9,FALSE)) | AS12: =IF(C12="","",VLOOKUP(C12,$C$102:$T$106,12,FALSE)) | AV12: =IFERROR(__xludf.DUMMYFUNCTION("IFERROR(IF(AY11>=0.5,SPARKLINE(AY11,{""charttype"",""bar"";""max"",1;""color1"",""FFB400""}),SPARKLINE(AY11,{""charttype"",""bar"";""max"",1;""color1"",""80E12A""})),"""")"),"") | BR12: 매도 | BT12: =IF(T19="","",(N8-T19*N8/(0.5*P8))) | BW12: =IF(AC8="","",ROUND(AC8/4,0)) | BY12: =IF(AF8="","",AF8*(1+$AY$14+BT12)) | CB12: =IF(T19="","",(N8-T19*N8/(0.5*P8))) | CE12: =IF(AC8="","",IF(ROUND(AC8/T19,0)>AC8,AC8,ROUND(AC8/T19,0))) | CG12: =IF(AF8="","",AF8*(1+$AY$14+CB12))
B13: 7 | E13: V3.0 | J13: 반 | K13: =IF(J13="완",IF(AN85=0,"",G13+AN85),IF(J13="반",IF(AN85>0,G13+(AN85/2),IF(AN85=0,"",G13+AN85)),"")) | N13: 0.15 | P13: 20 | R13: FALSE | S13: =IF(G13="","",IF(R13=TRUE,IF(K13="",G13/P13,K13/P13),IF(K13-G13>0,K13/P13,G13/P13))) | U13: =IFERROR(IF(G13="","",ROUNDDOWN(S13/AK13,0)),"") | AI13: =IF(C13="","",VLOOKUP(C13,$C$102:$T$106,17,FALSE)) | AK13: =IF(C13="","",VLOOKUP(C13,$C$102:$T$106,3,FALSE)) | AM13: =IF(C13="","",VLOOKUP(C13,$C$102:$T$106,6,FALSE)) | AP13: =IF(C13="","",VLOOKUP(C13,$C$102:$T$106,9,FALSE)) | AS13: =IF(C13="","",VLOOKUP(C13,$C$102:$T$106,12,FALSE)) | AV13: 1일 매입액 | AY13: =SUM(R7:T16) -> 0 | BE13: ↔원금 | BG13: =IFERROR(BE8/AY7,0) -> 0
B14: 8 | E14: V3.0 | J14: 반 | K14: =IF(J14="완",IF(BB85=0,"",G14+BB85),IF(J14="반",IF(BB85>0,G14+(BB85/2),IF(BB85=0,"",G14+BB85)),"")) | N14: 0.15 | P14: 20 | R14: FALSE | S14: =IF(G14="","",IF(R14=TRUE,IF(K14="",G14/P14,K14/P14),IF(K14-G14>0,K14/P14,G14/P14))) | U14: =IFERROR(IF(G14="","",ROUNDDOWN(S14/AK14,0)),"") | AI14: =IF(C14="","",VLOOKUP(C14,$C$102:$T$106,17,FALSE)) | AK14: =IF(C14="","",VLOOKUP(C14,$C$102:$T$106,3,FALSE)) | AM14: =IF(C14="","",VLOOKUP(C14,$C$102:$T$106,6,FALSE)) | AP14: =IF(C14="","",VLOOKUP(C14,$C$102:$T$106,9,FALSE)) | AS14: =IF(C14="","",VLOOKUP(C14,$C$102:$T$106,12,FALSE)) | AV14: 매도수수료 | AY14: 0.0002 | BE14: =IFERROR(__xludf.DUMMYFUNCTION("IFERROR(SPARKLINE(BG13,{""charttype"", ""column"";""color"",""FF0000""; ""negcolor"", ""0000FF""; ""ymin"", -0.3 ; ""ymax"", +0.2 ;""axis"",true ; ""axiscolor"",""000000""}),"""")"),"") | BT14: =$N$8 -> 0.15 | BW14: =IF(AC8="","",AC8-BW12) | BY14: =IF(AF8="","",AF8*(1+N8+$AY$14)) | CB14: =$N$8 -> 0.15 | CE14: =IF(AC8="","",AC8-CE12) | CG14: =IF(AF8="","",AF8*(1+N8+$AY$14))
B15: 9 | E15: V3.0 | J15: 반 | K15: =IF(J15="완",IF(L98=0,"",G15+L98),IF(J15="반",IF(L98>0,G15+(L98/2),IF(L98=0,"",G15+L98)),"")) | N15: 0.15 | P15: 20 | R15: FALSE | S15: =IF(G15="","",IF(R15=TRUE,IF(K15="",G15/P15,K15/P15),IF(K15-G15>0,K15/P15,G15/P15))) | U15: =IFERROR(IF(G15="","",ROUNDDOWN(S15/AK15,0)),"") | AI15: =IF(C15="","",VLOOKUP(C15,$C$102:$T$106,17,FALSE)) | AK15: =IF(C15="","",VLOOKUP(C15,$C$102:$T$106,3,FALSE)) | AM15: =IF(C15="","",VLOOKUP(C15,$C$102:$T$106,6,FALSE)) | AP15: =IF(C15="","",VLOOKUP(C15,$C$102:$T$106,9,FALSE)) | AS15: =IF(C15="","",VLOOKUP(C15,$C$102:$T$106,12,FALSE)) | BJ15: 큰수 기준 | BP15: 3 | BR15: 매수 | BT15: 평단 | BW15: =IF(BY15>BY17,"",IF(AA19<0.5,IF(AF9="","",IF(BY16<BY17,ROUNDDOWN(S9/BY15,0)-BW16,ROUNDDOWN(S9/BY15,0)-BW17)),"")) | BY15: =IF(AF9="","",AF9) | CB15: 평단 | CG15: =IF(AF9="","",AF9)
B16: 10 | E16: V3.0 | J16: 반 | K16: =IF(J16="완",IF(Z98=0,"",G16+Z98),IF(J16="반",IF(Z98>0,G16+(Z98/2),IF(Z98=0,"",G16+Z98)),"")) | N16: 0.15 | P16: 20 | R16: FALSE | S16: =IF(G16="","",IF(R16=TRUE,IF(K16="",G16/P16,K16/P16),IF(K16-G16>0,K16/P16,G16/P16))) | U16: =IFERROR(IF(G16="","",ROUNDDOWN(S16/AK16,0)),"") | AI16: =IF(C16="","",VLOOKUP(C16,$C$102:$T$106,17,FALSE)) | AK16: =IF(C16="","",VLOOKUP(C16,$C$102:$T$106,3,FALSE)) | AM16: =IF(C16="","",VLOOKUP(C16,$C$102:$T$106,6,FALSE)) | AP16: =IF(C16="","",VLOOKUP(C16,$C$102:$T$106,9,FALSE)) | AS16: =IF(C16="","",VLOOKUP(C16,$C$102:$T$106,12,FALSE)) | AV16: TODAY | AY16: =TODAY() -> 46224 | BJ16: 0.15 | BT16: =IF(AD19="",N9,(N9-AD19*N9/(0.5*P9))) -> 0.15 | BW16: =IF(AC9="","",IF(BY16>BY17,"",IF(AA19<0.5,ROUNDDOWN(S9/2/BY16,0),IF(Y23<S9,ROUNDDOWN(Y23/BY16,0),ROUNDDOWN(S9/BY16,0))))) | BY16: =IF(AF9="","",AF9*(1+BT16)) | CB16: =IF(AD19="",N9,(N9-AD19*N9/(0.5*P9))) -> 0.15 | CE16: =IF(AC9="","",IF(CG16>CG17,"",IF(Y23<S9,ROUNDDOWN(Y23/CG16,0),ROUNDDOWN(S9/CG16,0)))) | CG16: =IF(AF9="","",AF9*(1+CB16))
BT17: 큰수 | BW17: =IF(AC9="","",IF(BY16<BY17,"",IF(Y23<S9,ROUNDDOWN(Y23/BY17,0),IF(BY15>BY17,ROUNDDOWN(S9/BY17,0),ROUNDDOWN(S9/2/BY17,0))))) | BY17: =IF(AF9="","",AK9*(1+BJ16)) | CB17: 큰수 | CE17: =IF(AC9="","",IF(CG16<CG17,"",IF(Y23<S9,ROUNDDOWN(Y23/CG17,0),ROUNDDOWN(S9/CG17,0)))) | CG17: =IF(AF9="","",AK9*(1+BJ16))
B18: 1 | C18: =IF(C7="","",C7) | J18: =IF(E7="","",E7) -> V3.0 | L18: 2 | M18: =IF(C8="","",C8) | T18: =IF(E8="","",E8) -> V3.0 | V18: 3 | W18: =IF(C9="","",C9) | AD18: =IF(E9="","",E9) -> V3.0 | AF18: 4 | AG18: =IF(C10="","",C10) | AN18: =IF(E10="","",E10) -> V3.0 | AP18: 5 | AQ18: =IF(C11="","",C11) | AX18: =IF(E11="","",E11) -> V3.0 | BA18: * 초록색은 LOC 매도 (단, 가격에 MOC라고 나올 경우에는 MOC매도), 파란색은 지정가 매도 | BR18: 매도 | BT18: =IF(AD19="","",(N9-AD19*N9/(0.5*P9))) | BW18: =IF(AC9="","",ROUND(AC9/4,0)) | BY18: =IF(AF9="","",AF9*(1+$AY$14+BT18)) | CB18: =IF(AD19="","",(N9-AD19*N9/(0.5*P9))) | CE18: =IF(AC9="","",IF(ROUND(AC9/AD19,0)>AC9,AC9,ROUND(AC9/AD19,0))) | CG18: =IF(AF9="","",AF9*(1+$AY$14+CB18))
C19: =IFERROR(__xludf.DUMMYFUNCTION("IFERROR(IF(G19>=0.5,SPARKLINE(G19,{""charttype"",""bar"";""max"",1;""color1"",""FFB400""}),SPARKLINE(G19,{""charttype"",""bar"";""max"",1;""color1"",""80E12A""})),"""")"),"") | G19: =IFERROR(IF(J19="","",J19/P7),"") | J19: =IFERROR(IF(E24<1,P7,IF(J18="V3.0",ROUNDUP(E20/S7,1),ROUND(E20/S7,2))),"") | M19: =IFERROR(__xludf.DUMMYFUNCTION("IFERROR(IF(Q19>=0.5,SPARKLINE(Q19,{""charttype"",""bar"";""max"",1;""color1"",""FFB400""}),SPARKLINE(Q19,{""charttype"",""bar"";""max"",1;""color1"",""80E12A""})),"""")"),"") | Q19: =IFERROR(IF(T19="","",T19/P8),"") | T19: =IFERROR(IF(O24<1,P8,IF(T18="V3.0",ROUNDUP(O20/S8,1),ROUND(O20/S8,2))),"") | W19: =IFERROR(__xludf.DUMMYFUNCTION("IFERROR(IF(AA19>=0.5,SPARKLINE(AA19,{""charttype"",""bar"";""max"",1;""color1"",""FFB400""}),SPARKLINE(AA19,{""charttype"",""bar"";""max"",1;""color1"",""80E12A""})),"""")"),"") | AA19: =IFERROR(IF(AD19="","",AD19/P9),"") | AD19: =IFERROR(IF(Y24<1,P9,IF(AD18="V3.0",ROUNDUP(Y20/S9,1),ROUND(Y20/S9,2))),"") | AG19: =IFERROR(__xludf.DUMMYFUNCTION("IFERROR(IF(AK19>=0.5,SPARKLINE(AK19,{""charttype"",""bar"";""max"",1;""color1"",""FFB400""}),SPARKLINE(AK19,{""charttype"",""bar"";""max"",1;""color1"",""80E12A""})),"""")"),"") | AK19: =IFERROR(IF(AN19="","",AN19/P10),"") | AN19: =IFERROR(IF(AI24<1,P10,IF(AN18="V3.0",ROUNDUP(AI20/S10,1),ROUND(AI20/S10,2))),"") | AQ19: =IFERROR(__xludf.DUMMYFUNCTION("IFERROR(IF(AU19>=0.5,SPARKLINE(AU19,{""charttype"",""bar"";""max"",1;""color1"",""FFB400""}),SPARKLINE(AU19,{""charttype"",""bar"";""max"",1;""color1"",""80E12A""})),"""")"),"") | AU19: =IFERROR(IF(AX19="","",AX19/P11),"") | AX19: =IFERROR(IF(AS24<1,P11,IF(AX18="V3.0",ROUNDUP(AS20/S11,1),ROUND(AS20/S11,2))),"")
B20: 매입금액 | E20: =IF(AC7="","",AC7*AF7) | I20: =IFERROR(__xludf.DUMMYFUNCTION("IFERROR(SPARKLINE(I24,{""charttype"", ""column"";""color"",""FF0000""; ""negcolor"", ""0000FF""; ""ymin"", -0.3 ; ""ymax"", +0.2 ;""axis"",true ; ""axiscolor"",""000000""}),"""")"),"") | L20: 매입금액 | O20: =IF(AC8="","",AC8*AF8) | S20: =IFERROR(__xludf.DUMMYFUNCTION("IFERROR(SPARKLINE(S24,{""charttype"", ""column"";""color"",""FF0000""; ""negcolor"", ""0000FF""; ""ymin"", -0.3 ; ""ymax"", +0.2 ;""axis"",true ; ""axiscolor"",""000000""}),"""")"),"") | V20: 매입금액 | Y20: =IF(AC9="","",AC9*AF9) | AC20: =IFERROR(__xludf.DUMMYFUNCTION("IFERROR(SPARKLINE(AC24,{""charttype"", ""column"";""color"",""FF0000""; ""negcolor"", ""0000FF""; ""ymin"", -0.3 ; ""ymax"", +0.2 ;""axis"",true ; ""axiscolor"",""000000""}),"""")"),"") | AF20: 매입금액 | AI20: =IF(AC10="","",AC10*AF10) | AM20: =IFERROR(__xludf.DUMMYFUNCTION("IFERROR(SPARKLINE(AM24,{""charttype"", ""column"";""color"",""FF0000""; ""negcolor"", ""0000FF""; ""ymin"", -0.3 ; ""ymax"", +0.2 ;""axis"",true ; ""axiscolor"",""000000""}),"""")"),"") | AP20: 매입금액 | AS20: =IF(AC11="","",AC11*AF11) | AW20: =IFERROR(__xludf.DUMMYFUNCTION("IFERROR(SPARKLINE(AW24,{""charttype"", ""column"";""color"",""FF0000""; ""negcolor"", ""0000FF""; ""ymin"", -0.3 ; ""ymax"", +0.2 ;""axis"",true ; ""axiscolor"",""000000""}),"""")"),"") | BT20: =$N$9 -> 0.15 | BW20: =IF(AC9="","",AC9-BW18) | BY20: =IF(AF9="","",AF9*(1+N9+$AY$14)) | CB20: =$N$9 -> 0.15 | CE20: =IF(AC9="","",AC9-CE18) | CG20: =IF(AF9="","",AF9*(1+N9+$AY$14))
B21: 평가금액 | E21: =IF(AC7="","",AC7*AK7) | L21: 평가금액 | O21: =IF(AC8="","",AC8*AK8) | V21: 평가금액 | Y21: =IF(AC9="","",AC9*AK9) | AF21: 평가금액 | AI21: =IF(AC10="","",AC10*AK10) | AP21: 평가금액 | AS21: =IF(AC11="","",AC11*AK11) | BA21: * 큰 하락이 발생하였을 때 1회 매수금을 완전히 소진하여 매수하려면, 떡락 매수에 있는 가격 별로 1주씩 추가로 주문! | BP21: 4 | BR21: 매수 | BT21: 평단 | BW21: =IF(BY21>BY23,"",IF(AK19<0.5,IF(AF10="","",IF(BY22<BY23,ROUNDDOWN(S10/BY21,0)-BW22,ROUNDDOWN(S10/BY21,0)-BW23)),"")) | BY21: =IF(AF10="","",AF10) | CB21: 평단 | CG21: =IF(AF10="","",AF10)
B22: 손익 | E22: =IF(E21="","",E21-E20) | L22: 손익 | O22: =IF(O21="","",O21-O20) | V22: 손익 | Y22: =IF(Y21="","",Y21-Y20) | AF22: 손익 | AI22: =IF(AI21="","",AI21-AI20) | AP22: 손익 | AS22: =IF(AS21="","",AS21-AS20) | BT22: =IF(AN19="",N10,(N10-AN19*N10/(0.5*P10))) -> 0.15 | BW22: =IF(AC10="","",IF(BY22>BY23,"",IF(AK19<0.5,ROUNDDOWN(S10/2/BY22,0),IF(AI23<S10,ROUNDDOWN(AI23/BY22,0),ROUNDDOWN(S10/BY22,0))))) | BY22: =IF(AF10="","",AF10*(1+BT22)) | CB22: =IF(AN19="",N10,(N10-AN19*N10/(0.5*P10))) -> 0.15 | CE22: =IF(AC10="","",IF(CG22>CG23,"",IF(AI23<S10,ROUNDDOWN(AI23/CG22,0),ROUNDDOWN(S10/CG22,0)))) | CG22: =IF(AF10="","",AF10*(1+CB22))
B23: 남은원금 | E23: =IF(E20="","",IF(K7="",G7-E20,K7-E20)) | L23: 남은원금 | O23: =IF(O20="","",IF(K8="",G8-O20,K8-O20)) | V23: 남은원금 | Y23: =IF(Y20="","",IF(K9="",G9-Y20,K9-Y20)) | AF23: 남은원금 | AI23: =IF(AI20="","",IF(K10="",G10-AI20,K10-AI20)) | AP23: 남은원금 | AS23: =IF(AS20="","",IF(K11="",G11-AS20,K11-AS20)) | BT23: 큰수 | BW23: =IF(AC10="","",IF(BY22<BY23,"",IF(AI23<S10,ROUNDDOWN(AI23/BY23,0),IF(BY21>BY23,ROUNDDOWN(S10/BY23,0),ROUNDDOWN(S10/2/BY23,0))))) | BY23: =IF(AF10="","",AK10*(1+BJ16)) | CB23: 큰수 | CE23: =IF(AC10="","",IF(CG22<CG23,"",IF(AI23<S10,ROUNDDOWN(AI23/CG23,0),ROUNDDOWN(S10/CG23,0)))) | CG23: =IF(AF10="","",AK10*(1+BJ16))
B24: 매수가능 | E24: =IF(E23="","",ROUNDDOWN(E23/AK7,0)) | I24: =IFERROR(IF(E20="","",(E21-E20)/E20),"") | L24: 매수가능 | O24: =IF(O23="","",ROUNDDOWN(O23/AK8,0)) | S24: =IFERROR(IF(O20="","",(O21-O20)/O20),"") | V24: 매수가능 | Y24: =IF(Y23="","",ROUNDDOWN(Y23/AK9,0)) | AC24: =IFERROR(IF(Y20="","",(Y21-Y20)/Y20),"") | AF24: 매수가능 | AI24: =IF(AI23="","",ROUNDDOWN(AI23/AK10,0)) | AM24: =IFERROR(IF(AI20="","",(AI21-AI20)/AI20),"") | AP24: 매수가능 | AS24: =IF(AS23="","",ROUNDDOWN(AS23/AK11,0)) | AW24: =IFERROR(IF(AS20="","",(AS21-AS20)/AS20),"") | BR24: 매도 | BT24: =IF(AN19="","",(N10-AN19*N10/(0.5*P10))) | BW24: =IF(AC10="","",ROUND(AC10/4,0)) | BY24: =IF(AF10="","",AF10*(1+$AY$14+BT24)) | CB24: =IF(AN19="","",(N10-AN19*N10/(0.5*P10))) | CE24: =IF(AC10="","",IF(ROUND(AC10/AN19,0)>AC10,AC10,ROUND(AC10/AN19,0))) | CG24: =IF(AF10="","",AF10*(1+$AY$14+CB24))
B25: MOC매도 | F25: FALSE | G25: 0 | L25: MOC매도 | P25: FALSE | Q25: 0 | V25: MOC매도 | Z25: FALSE | AA25: 0 | AF25: MOC매도 | AJ25: FALSE | AK25: 0 | AP25: MOC매도 | AT25: FALSE | AU25: 0 | BA25: 메모
B26: 매수 | D26: =IF($J$18="V3.0",BT3,CB3) -> 평단 | G26: =IF(J18="V3.0",IF(AND(P7-1<J19,J19<=P7),"",BW3),IF(J19>(P7-1),"",CE3)) | I26: =IF(J18="V3.0",BY3,CG3) | L26: 매수 | N26: =IF($T$18="V3.0",BT9,CB9) -> 평단 | Q26: =IF(T18="V3.0",IF(AND(P8-1<T19,T19<=P8),"",BW9),IF(T19>(P8-1),"",CE9)) | S26: =IF(T18="V3.0",BY9,CG9) | V26: 매수 | X26: =IF($AD$18="V3.0",BT15,CB15) -> 평단 | AA26: =IF(AD18="V3.0",IF(AND(P9-1<AD19,AD19<=P9),"",BW15),IF(AD19>(P9-1),"",CE15)) | AC26: =IF(AD18="V3.0",BY15,CG15) | AF26: 매수 | AH26: =IF($AN$18="V3.0",BT21,CB21) -> 평단 | AK26: =IF(AN18="V3.0",IF(AND(P10-1<AN19,AN19<=P10),"",BW21),IF(AN19>(P10-1),"",CE21)) | AM26: =IF(AN18="V3.0",BY21,CG21) | AP26: 매수 | AR26: =IF($AX$18="V3.0",BT27,CB27) -> 평단 | AU26: =IF(AX18="V3.0",IF(AND(P11-1<AX19,AX19<=P11),"",BW27),IF(AX19>(P11-1),"",CE27)) | AW26: =IF(AX18="V3.0",BY27,CG27) | BT26: =$N$10 -> 0.15 | BW26: =IF(AC10="","",AC10-BW24) | BY26: =IF(AF10="","",AF10*(1+N10+$AY$14)) | CB26: =$N$10 -> 0.15 | CE26: =IF(AC10="","",AC10-CE24) | CG26: =IF(AF10="","",AF10*(1+N10+$AY$14))
D27: =IF($J$18="V3.0",BT4,CB4) -> 0.15 | G27: =IF(J18="V3.0",IF(AND(P7-1<J19,J19<=P7),"",BW4),IF(J19>(P7-1),"",CE4)) | I27: =IF(J18="V3.0",BY4,CG4) | N27: =IF($T$18="V3.0",BT10,CB10) -> 0.15 | Q27: =IF(T18="V3.0",IF(AND(P8-1<T19,T19<=P8),"",BW10),IF(T19>(P8-1),"",CE10)) | S27: =IF(T18="V3.0",BY10,CG10) | X27: =IF($AD$18="V3.0",BT16,CB16) -> 0.15 | AA27: =IF(AD18="V3.0",IF(AND(P9-1<AD19,AD19<=P9),"",BW16),IF(AD19>(P9-1),"",CE16)) | AC27: =IF(AD18="V3.0",BY16,CG16) | AH27: =IF($AN$18="V3.0",BT22,CB22) -> 0.15 | AK27: =IF(AN18="V3.0",IF(AND(P10-1<AN19,AN19<=P10),"",BW22),IF(AN19>(P10-1),"",CE22)) | AM27: =IF(AN18="V3.0",BY22,CG22) | AR27: =IF($AX$18="V3.0",BT28,CB28) -> 0.15 | AU27: =IF(AX18="V3.0",IF(AND(P11-1<AX19,AX19<=P11),"",BW28),IF(AX19>(P11-1),"",CE28)) | AW27: =IF(AX18="V3.0",BY28,CG28) | BP27: 5 | BR27: 매수 | BT27: 평단 | BW27: =IF(BY27>BY29,"",IF(AU19<0.5,IF(AF11="","",IF(BY28<BY29,ROUNDDOWN(S11/BY27,0)-BW28,ROUNDDOWN(S11/BY27,0)-BW29)),"")) | BY27: =IF(AF11="","",AF11) | CB27: 평단 | CG27: =IF(AF11="","",AF11)
D28: =IF($J$18="V3.0",BT5,CB5) -> 큰수 | G28: =IF(J18="V3.0",IF(AND(P7-1<J19,J19<=P7),"",BW5),IF(J19>(P7-1),"",CE5)) | I28: =IF(J18="V3.0",BY5,CG5) | N28: =IF($T$18="V3.0",BT11,CB11) -> 큰수 | Q28: =IF(T18="V3.0",IF(AND(P8-1<T19,T19<=P8),"",BW11),IF(T19>(P8-1),"",CE11)) | S28: =IF(T18="V3.0",BY11,CG11) | X28: =IF($AD$18="V3.0",BT17,CB17) -> 큰수 | AA28: =IF(AD18="V3.0",IF(AND(P9-1<AD19,AD19<=P9),"",BW17),IF(AD19>(P9-1),"",CE17)) | AC28: =IF(AD18="V3.0",BY17,CG17) | AH28: =IF($AN$18="V3.0",BT23,CB23) -> 큰수 | AK28: =IF(AN18="V3.0",IF(AND(P10-1<AN19,AN19<=P10),"",BW23),IF(AN19>(P10-1),"",CE23)) | AM28: =IF(AN18="V3.0",BY23,CG23) | AR28: =IF($AX$18="V3.0",BT29,CB29) -> 큰수 | AU28: =IF(AX18="V3.0",IF(AND(P11-1<AX19,AX19<=P11),"",BW29),IF(AX19>(P11-1),"",CE29)) | AW28: =IF(AX18="V3.0",BY29,CG29) | BT28: =IF(AX19="",N11,(N11-AX19*N11/(0.5*P11))) -> 0.15 | BW28: =IF(AC11="","",IF(BY28>BY29,"",IF(AU19<0.5,ROUNDDOWN(S11/2/BY28,0),IF(AS23<S11,ROUNDDOWN(AS23/BY28,0),ROUNDDOWN(S11/BY28,0))))) | BY28: =IF(AF11="","",AF11*(1+BT28)) | CB28: =IF(AX19="",N11,(N11-AX19*N11/(0.5*P11))) -> 0.15 | CE28: =IF(AC11="","",IF(CG28>CG29,"",IF(AS23<S11,ROUNDDOWN(AS23/CG28,0),ROUNDDOWN(S11/CG28,0)))) | CG28: =IF(AF11="","",AF11*(1+CB28))
B29: 매도 | D29: =IF($J$18="V3.0",BT6,CB6) | G29: =IF(J18="V3.0",BW6,CE6) | I29: =IF(AND(P7-1<J19,J19<=P7),"MOC",IF(J18="V3.0",BY6,CG6)) | L29: 매도 | N29: =IF($T$18="V3.0",BT12,CB12) | Q29: =IF(T18="V3.0",BW12,CE12) | S29: =IF(AND(P8-1<T19,T19<=P8),"MOC",IF(T18="V3.0",BY12,CG12)) | V29: 매도 | X29: =IF($AD$18="V3.0",BT18,CB18) | AA29: =IF(AD18="V3.0",BW18,CE18) | AC29: =IF(AND(P9-1<AD19,AD19<=P9),"MOC",IF(AD18="V3.0",BY18,CG18)) | AF29: 매도 | AH29: =IF($AN$18="V3.0",BT24,CB24) | AK29: =IF(AN18="V3.0",BW24,CE24) | AM29: =IF(AND(P10-1<AN19,AN19<=P10),"MOC",IF(AN18="V3.0",BY24,CG24)) | AP29: 매도 | AR29: =IF($AX$18="V3.0",BT30,CB30) | AU29: =IF(AX18="V3.0",BW30,CE30) | AW29: =IF(AND(P11-1<AX19,AX19<=P11),"MOC",IF(AX18="V3.0",BY30,CG30)) | BT29: 큰수 | BW29: =IF(AC11="","",IF(BY28<BY29,"",IF(AS23<S11,ROUNDDOWN(AS23/BY29,0),IF(BY27>BY29,ROUNDDOWN(S11/BY29,0),ROUNDDOWN(S11/2/BY29,0))))) | BY29: =IF(AF11="","",AK11*(1+BJ16)) | CB29: 큰수 | CE29: =IF(AC11="","",IF(CG28<CG29,"",IF(AS23<S11,ROUNDDOWN(AS23/CG29,0),ROUNDDOWN(S11/CG29,0)))) | CG29: =IF(AF11="","",AK11*(1+BJ16))
D30: =IF($J$18="V3.0",BT7,CB7) | G30: =IF(J18="V3.0",BW7,CE7) | I30: =IF(J18="V3.0",BY7,CG7) | N30: =IF($T$18="V3.0",BT13,CB13) | Q30: =IF(T18="V3.0",BW13,CE13) | S30: =IF(T18="V3.0",BY13,CG13) | X30: =IF($AD$18="V3.0",BT19,CB19) | AA30: =IF(AD18="V3.0",BW19,CE19) | AC30: =IF(AD18="V3.0",BY19,CG19) | AH30: =IF($AN$18="V3.0",BT25,CB25) | AK30: =IF(AN18="V3.0",BW25,CE25) | AM30: =IF(AN18="V3.0",BY25,CG25) | AR30: =IF($AX$18="V3.0",BT31,CB31) | AU30: =IF(AX18="V3.0",BW31,CE31) | AW30: =IF(AX18="V3.0",BY31,CG31) | BR30: 매도 | BT30: =IF(AX19="","",(N11-AX19*N11/(0.5*P11))) | BW30: =IF(AC11="","",ROUND(AC11/4,0)) | BY30: =IF(AF11="","",AF11*(1+$AY$14+BT30)) | CB30: =IF(AX19="","",(N11-AX19*N11/(0.5*P11))) | CE30: =IF(AC11="","",IF(ROUND(AC11/AX19,0)>AC11,AC11,ROUND(AC11/AX19,0))) | CG30: =IF(AF11="","",AF11*(1+$AY$14+CB30))
D31: =IF($J$18="V3.0",BT8,CB8) -> 0.15 | G31: =IF(J18="V3.0",BW8,CE8) | I31: =IF(J18="V3.0",BY8,CG8) | N31: =IF($T$18="V3.0",BT14,CB14) -> 0.15 | Q31: =IF(T18="V3.0",BW14,CE14) | S31: =IF(T18="V3.0",BY14,CG14) | X31: =IF($AD$18="V3.0",BT20,CB20) -> 0.15 | AA31: =IF(AD18="V3.0",BW20,CE20) | AC31: =IF(AD18="V3.0",BY20,CG20) | AH31: =IF($AN$18="V3.0",BT26,CB26) -> 0.15 | AK31: =IF(AN18="V3.0",BW26,CE26) | AM31: =IF(AN18="V3.0",BY26,CG26) | AR31: =IF($AX$18="V3.0",BT32,CB32) -> 0.15 | AU31: =IF(AX18="V3.0",BW32,CE32) | AW31: =IF(AX18="V3.0",BY32,CG32)
BT32: =$N$11 -> 0.15 | BW32: =IF(AC11="","",AC11-BW30) | BY32: =IF(AF11="","",AF11*(1+N11+$AY$14)) | CB32: =$N$11 -> 0.15 | CE32: =IF(AC11="","",AC11-CE30) | CG32: =IF(AF11="","",AF11*(1+N11+$AY$14))
B33: 떡락 | D33: 하락률 | G33: 총 갯수 | I33: 가격 | L33: 떡락 | N33: 하락률 | Q33: 총 갯수 | S33: 가격 | V33: 떡락 | X33: 하락률 | AA33: 총 갯수 | AC33: 가격 | AF33: 떡락 | AH33: 하락률 | AK33: 총 갯수 | AM33: 가격 | AP33: 떡락 | AR33: 하락률 | AU33: 총 갯수 | AW33: 가격 | BP33: 6 | BR33: 매수 | BT33: 평단 | BW33: =IF(BY33>BY35,"",IF(G40<0.5,IF(AF12="","",IF(BY34<BY35,ROUNDDOWN(S12/BY33,0)-BW34,ROUNDDOWN(S12/BY33,0)-BW35)),"")) | BY33: =IF(AF12="","",AF12) | CB33: 평단 | CG33: =IF(AF12="","",AF12)
D34: =IFERROR(IF((I34-$AK$7)/$AK$7=-1,"",(I34-$AK$7)/$AK$7),"") | G34: =IF(SUM(G26:H28)>0,SUM(G26:H28)+1,"") | I34: =IFERROR(ROUNDDOWN($S$7/G34,2),"") | N34: =IFERROR(IF((S34-$AK$8)/$AK$8=-1,"",(S34-$AK$8)/$AK$8),"") | Q34: =IF(SUM(Q26:R28)>0,sum(Q26:R28)+1,"") | S34: =IFERROR(ROUNDDOWN($S$8/Q34,2),"") | X34: =IFERROR(IF((AC34-$AK$9)/$AK$9=-1,"",(AC34-$AK$9)/$AK$9),"") | AA34: =IF(SUM(AA26:AB28)>0,sum(AA26:AB28)+1,"") | AC34: =IFERROR(ROUNDDOWN($S$9/AA34,2),"") | AH34: =IFERROR(IF((AM34-$AK$10)/$AK$10=-1,"",(AM34-$AK$10)/$AK$10),"") | AK34: =IF(SUM(AK26:AL28)>0,sum(AK26:AL28)+1,"") | AM34: =IFERROR(ROUNDDOWN($S$10/AK34,2),"") | AR34: =IFERROR(IF((AW34-$AK$11)/$AK$11=-1,"",(AW34-$AK$11)/$AK$11),"") | AU34: =IF(SUM(AU26:AV28)>0,sum(AU26:AV28)+1,"") | AW34: =IFERROR(ROUNDDOWN($S$11/AU34,2),"") | BT34: =IF(J40="",N12,(N12-J40*N12/(0.5*P12))) -> 0.15 | BW34: =IF(AC12="","",IF(BY34>BY35,"",IF(G40<0.5,ROUNDDOWN(S12/2/BY34,0),IF(E44<S12,ROUNDDOWN(E44/BY34,0),ROUNDDOWN(S12/BY34,0))))) | BY34: =IF(AF12="","",AF12*(1+BT34)) | CB34: =IF(J40="",N12,(N12-J40*N12/(0.5*P12))) -> 0.15 | CE34: =IF(AC12="","",IF(CG34>CG35,"",IF(E44<S12,ROUNDDOWN(E44/CG34,0),ROUNDDOWN(S12/CG34,0)))) | CG34: =IF(AF12="","",AF12*(1+CB34))
D35: =IFERROR(IF((I35-$AK$7)/$AK$7=-1,"",(I35-$AK$7)/$AK$7),"") | G35: =IF(G34="","",G34+1) | I35: =IFERROR(ROUNDDOWN($S$7/G35,2),"") | N35: =IFERROR(IF((S35-$AK$8)/$AK$8=-1,"",(S35-$AK$8)/$AK$8),"") | Q35: =IF(Q34="","",Q34+1) | S35: =IFERROR(ROUNDDOWN($S$8/Q35,2),"") | X35: =IFERROR(IF((AC35-$AK$9)/$AK$9=-1,"",(AC35-$AK$9)/$AK$9),"") | AA35: =IF(AA34="","",AA34+1) | AC35: =IFERROR(ROUNDDOWN($S$9/AA35,2),"") | AH35: =IFERROR(IF((AM35-$AK$10)/$AK$10=-1,"",(AM35-$AK$10)/$AK$10),"") | AK35: =IF(AK34="","",AK34+1) | AM35: =IFERROR(ROUNDDOWN($S$10/AK35,2),"") | AR35: =IFERROR(IF((AW35-$AK$11)/$AK$11=-1,"",(AW35-$AK$11)/$AK$11),"") | AU35: =IF(AU34="","",AU34+1) | AW35: =IFERROR(ROUNDDOWN($S$11/AU35,2),"") | BT35: 큰수 | BW35: =IF(AC12="","",IF(BY34<BY35,"",IF(E44<S12,ROUNDDOWN(E44/BY35,0),IF(BY33>BY35,ROUNDDOWN(S12/BY35,0),ROUNDDOWN(S12/2/BY35,0))))) | BY35: =IF(AF12="","",AK12*(1+BJ16)) | CB35: 큰수 | CE35: =IF(AC12="","",IF(CG34<CG35,"",IF(E44<S12,ROUNDDOWN(E44/CG35,0),ROUNDDOWN(S12/CG35,0)))) | CG35: =IF(AF12="","",AK12*(1+BJ16))
D36: =IFERROR(IF((I36-$AK$7)/$AK$7=-1,"",(I36-$AK$7)/$AK$7),"") | G36: =IF(G35="","",G35+1) | I36: =IFERROR(ROUNDDOWN($S$7/G36,2),"") | N36: =IFERROR(IF((S36-$AK$8)/$AK$8=-1,"",(S36-$AK$8)/$AK$8),"") | Q36: =IF(Q35="","",Q35+1) | S36: =IFERROR(ROUNDDOWN($S$8/Q36,2),"") | X36: =IFERROR(IF((AC36-$AK$9)/$AK$9=-1,"",(AC36-$AK$9)/$AK$9),"") | AA36: =IF(AA35="","",AA35+1) | AC36: =IFERROR(ROUNDDOWN($S$9/AA36,2),"") | AH36: =IFERROR(IF((AM36-$AK$10)/$AK$10=-1,"",(AM36-$AK$10)/$AK$10),"") | AK36: =IF(AK35="","",AK35+1) | AM36: =IFERROR(ROUNDDOWN($S$10/AK36,2),"") | AR36: =IFERROR(IF((AW36-$AK$11)/$AK$11=-1,"",(AW36-$AK$11)/$AK$11),"") | AU36: =IF(AU35="","",AU35+1) | AW36: =IFERROR(ROUNDDOWN($S$11/AU36,2),"") | BR36: 매도 | BT36: =IF(J40="","",(N12-J40*N12/(0.5*P12))) | BW36: =IF(AC12="","",ROUND(AC12/4,0)) | BY36: =IF(AF12="","",AF12*(1+$AY$14+BT36)) | CB36: =IF(J40="","",(N12-J40*N12/(0.5*P12))) | CE36: =IF(AC12="","",IF(ROUND(AC12/J40,0)>AC12,AC12,ROUND(AC12/J40,0))) | CG36: =IF(AF12="","",AF12*(1+$AY$14+CB36))
D37: =IFERROR(IF((I37-$AK$7)/$AK$7=-1,"",(I37-$AK$7)/$AK$7),"") | G37: =IF(G36="","",G36+1) | I37: =IFERROR(ROUNDDOWN($S$7/G37,2),"") | N37: =IFERROR(IF((S37-$AK$8)/$AK$8=-1,"",(S37-$AK$8)/$AK$8),"") | Q37: =IF(Q36="","",Q36+1) | S37: =IFERROR(ROUNDDOWN($S$8/Q37,2),"") | X37: =IFERROR(IF((AC37-$AK$9)/$AK$9=-1,"",(AC37-$AK$9)/$AK$9),"") | AA37: =IF(AA36="","",AA36+1) | AC37: =IFERROR(ROUNDDOWN($S$9/AA37,2),"") | AH37: =IFERROR(IF((AM37-$AK$10)/$AK$10=-1,"",(AM37-$AK$10)/$AK$10),"") | AK37: =IF(AK36="","",AK36+1) | AM37: =IFERROR(ROUNDDOWN($S$10/AK37,2),"") | AR37: =IFERROR(IF((AW37-$AK$11)/$AK$11=-1,"",(AW37-$AK$11)/$AK$11),"") | AU37: =IF(AU36="","",AU36+1) | AW37: =IFERROR(ROUNDDOWN($S$11/AU37,2),"")
BT38: =$N$12 -> 0.15 | BW38: =IF(AC12="","",AC12-BW36) | BY38: =IF(AF12="","",AF12*(1+N12+$AY$14)) | CB38: =$N$12 -> 0.15 | CE38: =IF(AC12="","",AC12-CE36) | CG38: =IF(AF12="","",AF12*(1+N12+$AY$14))
B39: 6 | C39: =IF(C12="","",C12) | J39: =IF(E12="","",E12) -> V3.0 | L39: 7 | M39: =IF(C13="","",C13) | T39: =IF(E13="","",E13) -> V3.0 | V39: 8 | W39: =IF(C14="","",C14) | AD39: =IF(E14="","",E14) -> V3.0 | AF39: 9 | AG39: =IF(C15="","",C15) | AN39: =IF(E15="","",E15) -> V3.0 | AP39: 10 | AQ39: =IF(C16="","",C16) | AX39: =IF(E16="","",E16) -> V3.0 | BP39: 7 | BR39: 매수 | BT39: 평단 | BW39: =IF(BY39>BY41,"",IF(Q40<0.5,IF(AF13="","",IF(BY40<BY41,ROUNDDOWN(S13/BY39,0)-BW40,ROUNDDOWN(S13/BY39,0)-BW41)),"")) | BY39: =IF(AF13="","",AF13) | CB39: 평단 | CG39: =IF(AF13="","",AF13)
C40: =IFERROR(__xludf.DUMMYFUNCTION("IFERROR(IF(G40>=0.5,SPARKLINE(G40,{""charttype"",""bar"";""max"",1;""color1"",""FFB400""}),SPARKLINE(G40,{""charttype"",""bar"";""max"",1;""color1"",""80E12A""})),"""")"),"") | G40: =IFERROR(IF(J40="","",J40/P12),"") | J40: =IFERROR(IF(E45<1,P12,IF(J39="V3.0",ROUNDUP(E41/S12,1),ROUND(E41/S12,2))),"") | M40: =IFERROR(__xludf.DUMMYFUNCTION("IFERROR(IF(Q40>=0.5,SPARKLINE(Q40,{""charttype"",""bar"";""max"",1;""color1"",""FFB400""}),SPARKLINE(Q40,{""charttype"",""bar"";""max"",1;""color1"",""80E12A""})),"""")"),"") | Q40: =IFERROR(IF(T40="","",T40/P13),"") | T40: =IFERROR(IF(O45<1,P13,IF(T39="V3.0",ROUNDUP(O41/S13,1),ROUND(O41/S13,2))),"") | W40: =IFERROR(__xludf.DUMMYFUNCTION("IFERROR(IF(AA40>=0.5,SPARKLINE(AA40,{""charttype"",""bar"";""max"",1;""color1"",""FFB400""}),SPARKLINE(AA40,{""charttype"",""bar"";""max"",1;""color1"",""80E12A""})),"""")"),"") | AA40: =IFERROR(IF(AD40="","",AD40/P14),"") | AD40: =IFERROR(IF(Y45<1,P14,IF(AD39="V3.0",ROUNDUP(Y41/S14,1),ROUND(Y41/S14,2))),"") | AG40: =IFERROR(__xludf.DUMMYFUNCTION("IFERROR(IF(AK40>=0.5,SPARKLINE(AK40,{""charttype"",""bar"";""max"",1;""color1"",""FFB400""}),SPARKLINE(AK40,{""charttype"",""bar"";""max"",1;""color1"",""80E12A""})),"""")"),"") | AK40: =IFERROR(IF(AN40="","",AN40/P15),"") | AN40: =IFERROR(IF(AI45<1,P15,IF(AN39="V3.0",ROUNDUP(AI41/S15,1),ROUND(AI41/S15,2))),"") | AQ40: =IFERROR(__xludf.DUMMYFUNCTION("IFERROR(IF(AU40>=0.5,SPARKLINE(AU40,{""charttype"",""bar"";""max"",1;""color1"",""FFB400""}),SPARKLINE(AU40,{""charttype"",""bar"";""max"",1;""color1"",""80E12A""})),"""")"),"") | AU40: =IFERROR(IF(AX40="","",AX40/P16),"") | AX40: =IFERROR(IF(AS45<1,P16,IF(AX39="V3.0",ROUNDUP(AS41/S16,1),ROUND(AS41/S16,2))),"") | BT40: =IF(T40="",N13,(N13-T40*N13/(0.5*P13))) -> 0.15 | BW40: =IF(AC13="","",IF(BY40>BY41,"",IF(Q40<0.5,ROUNDDOWN(S13/2/BY40,0),IF(O44<S13,ROUNDDOWN(O44/BY40,0),ROUNDDOWN(S13/BY40,0))))) | BY40: =IF(AF13="","",AF13*(1+BT40)) | CB40: =IF(T40="",N13,(N13-T40*N13/(0.5*P13))) -> 0.15 | CE40: =IF(AC13="","",IF(CG40>CG41,"",IF(O44<S13,ROUNDDOWN(O44/CG40,0),ROUNDDOWN(S13/CG40,0)))) | CG40: =IF(AF13="","",AF13*(1+CB40))
...

Sheet 기본1
B2: 라오어 무한 매수법 | J2: 언이시트 | N2: 기본 1 | BT2: V1 | CB2: V2 | CJ2: V2.1 | CR2: V2.2
BP3: 1 | BR3: 매수 | BT3: 평단 | BW3: =IF(BY3>BY5,"",IF(E23<O7,IF(BY4<BY5,ROUNDDOWN(E23/BY3-BW4,0),ROUNDDOWN(E23/BY3-BW5,0)),IF(AC7="","",IF(BY4<BY5,ROUNDDOWN(O7/BY3-BW4,0),ROUNDDOWN(O7/BY3-BW5,0))))) | BY3: =IF(AC7="","",AC7) | CB3: 평단 | CE3: =IF(Z7="","",IF(CG3>CG5,"",IF(G19>=0.5,IF(O7>E23,ROUNDDOWN(E23/CG3,0),ROUNDDOWN(O7/CG3,0)),IF(AC7="","",IF(CG4<CG5,ROUNDDOWN(O7/CG3,0)-CE4,ROUNDDOWN(O7/CG3,0)-CE5))))) | CG3: =IF(AC7="","",AC7) | CJ3: 평단 | CM3: =IF(Z7="","",IF(CO3>CO5,"",IF(G19>=0.5,IF(O7>E23,ROUNDDOWN(E23/CO3,0),ROUNDDOWN(O7/CO3,0)),IF(AC7="","",IF(CO4<CO5,ROUNDDOWN(O7/CO3,0)-CM4,ROUNDDOWN(O7/CO3,0)-CM5))))) | CO3: =IF(AC7="","",AC7) | CR3: 평단 | CU3: =IF(CW3>CW5,"",IF(G19<0.5,IF(AC7="","",IF(CW4<CW5,ROUNDDOWN(O7/CW3,0)-CU4,ROUNDDOWN(O7/CW3,0)-CU5)),"")) | CW3: =IF(AC7="","",AC7)
BT4: =$J$7 -> 0.1 | BW4: =IF(O7>E23,IF(BY4<BY5,ROUNDDOWN(E23/2/BY4,0),""),IF(BY4<BY5,ROUNDDOWN(O7/2/BY4,0),"")) | BY4: =IF(AC7="","",AC7*(1+J7)) | CB4: =$J$7/2 -> 0.05 | CE4: =IF(G19>=0.5,"",IF(CG4<CG5,ROUNDDOWN(O7/2/CG4,0),"")) | CG4: =IF(AC7="","",AC7*(1+J7/2)) | CJ4: =$J$7/2 -> 0.05 | CM4: =IF(G19>=0.5,"",IF(CO4<CO5,ROUNDDOWN(O7/2/CO4,0),"")) | CO4: =IF(AC7="","",AC7*(1+J7/2)) | CR4: =IF(J19="",J7,(J7-J19*J7/20*(40/M7))) -> 0.1 | CU4: =IF(Z7="","",IF(CW4>CW5,"",IF(G19<0.5,ROUNDDOWN(O7/2/CW4,0),IF(E23<O7,ROUNDDOWN(E23/CW4,0),ROUNDDOWN(O7/CW4,0))))) | CW4: =IF(AC7="","",AC7*(1+CR4))
C5: 첫 매수 시 기록 | Z5: 매일 기록 | AF5: 종목 정보 | AS5: 시드 현황 | BT5: 큰수 | BW5: =IF(O7>E23,IF(BY4>BY5,ROUNDDOWN(E23/BY5,0),""),IF(BY4>BY5,IF(BY3>BY5,ROUNDDOWN(O7/BY5,0),ROUNDDOWN(O7/2/BY5,0)),"")) | BY5: =IF(AC7="","",AH7*(1+BG16)) | CB5: 큰수 | CE5: =IF(Z7="","",IF(G19>=0.5,IF(E23<O7,ROUNDDOWN(E23/CG5,0)-CE3,ROUNDDOWN(O7/CG5,0)-CE3),IF(CG4>CG5,IF(CG3>CG5,ROUNDDOWN(O7/CG5,0),ROUNDDOWN(O7/2/CG5,0)),""))) | CG5: =IF(AC7="","",AH7*(1+BG16)) | CJ5: 큰수 | CM5: =IF(Z7="","",IF(G19>=0.5,IF(E23<O7,ROUNDDOWN(E23/CO5,0)-CM3,ROUNDDOWN(O7/CO5,0)-CM3),IF(CO4>CO5,IF(CO3>CO5,ROUNDDOWN(O7/CO5,0),ROUNDDOWN(O7/2/CO5,0)),""))) | CO5: =IF(AC7="","",AH7*(1+BG16)) | CR5: 큰수 | CU5: =IF(Z7="","",IF(CW4<CW5,"",IF(E23<O7,ROUNDDOWN(E23/CW5,0),IF(CW3>CW5,ROUNDDOWN(O7/CW5,0),ROUNDDOWN(O7/2/CW5,0))))) | CW5: =IF(AC7="","",AH7*(1+BG16))
C6: 종목 | E6: 매수법 | G6: 원금 | J6: 매도지점 | M6: 분할 | O6: 매수액 | R6: 매수량 | T6: 매수시작일 | W6: 최초매입가 | Z6: 잔고수량 | AC6: 평단가 | AF6: RSI | AH6: 현재가 | AJ6: =H84 -> 추세(10) | AM6: 전일대비 | AP6: 등락률 | BR6: 매도 | CJ6: 0 | CM6: =IF(Z7="","",IF(G19>=0.5,(ROUND(Z7/4,0)),"")) | CO6: =IF(AC7="","",AC7*(1+$AV$14)) | CR6: =IF(J19="","",(J7-J19*J7/20*(40/M7))) | CU6: =IF(Z7="","",ROUND(Z7/4,0)) | CW6: =IF(AC7="","",IF(AND(39*(M7/40)<J19,J19<=40*(M7/40)),"MOC",AC7*(1+$AV$14+CR6)))
B7: 1 | E7: V2.2 | J7: 0.1 | M7: 40 | O7: =IF(G7="","",G7/M7) | R7: =IFERROR(IF(G7="","",ROUNDDOWN(O7/AH7,0)),"") | AF7: =IF(C7="","",VLOOKUP(C7,$C$85:$T$110,17,FALSE)) | AH7: =IF(C7="","",VLOOKUP(C7,$C$85:$T$110,3,FALSE)) | AJ7: =IF(C7="","",VLOOKUP(C7,$C$85:$T$110,6,FALSE)) | AM7: =IF(C7="","",VLOOKUP(C7,$C$85:$T$110,9,FALSE)) | AP7: =IF(C7="","",VLOOKUP(C7,$C$85:$T$110,12,FALSE)) | AS7: 원금 합계 | AV7: =IF(SUM(G7:I16)=0,"",SUM(G7:I16)) | AZ7: 평가금 | BB7: =IF(AV9="","",E21+O21+Y21+AI21+AS21+E36+O36+Y36+AI36+AS36) | CB7: =$J$7/2 -> 0.05 | CE7: =IF(Z7="","",IF(G19>=0.5,(ROUND(Z7/2,0)),"")) | CG7: =IF(AC7="","",AC7*(1+J7/2+$AV$14)) | CJ7: =$J$7/2 -> 0.05 | CM7: =IF(Z7="","",ROUND(Z7/4,0)) | CO7: =IF(AC7="","",AC7*(1+J7/2+$AV$14))
B8: 2 | E8: V2.2 | J8: 0.1 | M8: 40 | O8: =IF(G8="","",G8/M8) | R8: =IFERROR(IF(G8="","",ROUNDDOWN(O8/AH8,0)),"") | AF8: =IF(C8="","",VLOOKUP(C8,$C$85:$T$110,17,FALSE)) | AH8: =IF(C8="","",VLOOKUP(C8,$C$85:$T$110,3,FALSE)) | AJ8: =IF(C8="","",VLOOKUP(C8,$C$85:$T$110,6,FALSE)) | AM8: =IF(C8="","",VLOOKUP(C8,$C$85:$T$110,9,FALSE)) | AP8: =IF(C8="","",VLOOKUP(C8,$C$85:$T$110,12,FALSE)) | AZ8: 손익 | BB8: =IF(BB7="","",BB7-AV9) | BT8: =$J$7 -> 0.1 | BW8: =IF(Z7="","",Z7) | BY8: =IF(AC7="","",AC7*(1+J7+$AV$14)) | CB8: =$J$7 -> 0.1 | CE8: =IF(CE7="",Z7,Z7-CE7) | CG8: =IF(AC7="","",AC7*(1+J7+$AV$14)) | CJ8: =$J$7 -> 0.1 | CM8: =IF(Z7="","",IF(G19<0.5,Z7-CM7,Z7-CM6-CM7)) | CO8: =IF(AC7="","",AC7*(1+J7+$AV$14)) | CR8: =$J$7 -> 0.1 | CU8: =IF(Z7="","",Z7-CU6) | CW8: =IF(AC7="","",AC7*(1+J7+$AV$14))
B9: 3 | E9: V2.2 | J9: 0.1 | M9: 40 | O9: =IF(G9="","",G9/M9) | R9: =IFERROR(IF(G9="","",ROUNDDOWN(O9/AH9,0)),"") | AF9: =IF(C9="","",VLOOKUP(C9,$C$85:$T$110,17,FALSE)) | AH9: =IF(C9="","",VLOOKUP(C9,$C$85:$T$110,3,FALSE)) | AJ9: =IF(C9="","",VLOOKUP(C9,$C$85:$T$110,6,FALSE)) | AM9: =IF(C9="","",VLOOKUP(C9,$C$85:$T$110,9,FALSE)) | AP9: =IF(C9="","",VLOOKUP(C9,$C$85:$T$110,12,FALSE)) | AS9: 매입 금액 | AV9: =IF(AV7="","",E20+O20+Y20+AI20+AS20+E35+O35+Y35+AI35+AS35) | AZ9: 수익률 | BB9: ↔투입 | BD9: =IFERROR(BB8/AV9,0) -> 0 | BP9: 2 | BR9: 매수 | BT9: 평단 | BW9: =IF(BY9>BY11,"",IF(O23<O8,IF(BY10<BY11,ROUNDDOWN(O23/BY9-BW10,0),ROUNDDOWN(O23/BY9-BW11,0)),IF(AC8="","",IF(BY10<BY11,ROUNDDOWN(O8/BY9-BW10,0),ROUNDDOWN(O8/BY9-BW11,0))))) | BY9: =IF(AC8="","",AC8) | CB9: 평단 | CE9: =IF(Z8="","",IF(CG9>CG11,"",IF(Q19>=0.5,IF(O8>O23,ROUNDDOWN(O23/CG9,0),ROUNDDOWN(O8/CG9,0)),IF(AC8="","",IF(CG10<CG11,ROUNDDOWN(O8/CG9,0)-CE10,ROUNDDOWN(O8/CG9,0)-CE11))))) | CG9: =IF(AC8="","",AC8) | CJ9: 평단 | CM9: =IF(Z8="","",IF(CO9>CO11,"",IF(Q19>=0.5,IF(O8>O23,ROUNDDOWN(O23/CO9,0),ROUNDDOWN(O8/CO9,0)),IF(AC8="","",IF(CO10<CO11,ROUNDDOWN(O8/CO9,0)-CM10,ROUNDDOWN(O8/CO9,0)-CM11))))) | CO9: =IF(AC8="","",AC8) | CR9: 평단 | CU9: =IF(CW9>CW11,"",IF(Q19<0.5,IF(AC8="","",IF(CW10<CW11,ROUNDDOWN(O8/CW9,0)-CU10,ROUNDDOWN(O8/CW9,0)-CU11)),"")) | CW9: =IF(AC8="","",AC8)
B10: 4 | E10: V2.2 | J10: 0.1 | M10: 40 | O10: =IF(G10="","",G10/M10) | R10: =IFERROR(IF(G10="","",ROUNDDOWN(O10/AH10,0)),"") | AF10: =IF(C10="","",VLOOKUP(C10,$C$85:$T$110,17,FALSE)) | AH10: =IF(C10="","",VLOOKUP(C10,$C$85:$T$110,3,FALSE)) | AJ10: =IF(C10="","",VLOOKUP(C10,$C$85:$T$110,6,FALSE)) | AM10: =IF(C10="","",VLOOKUP(C10,$C$85:$T$110,9,FALSE)) | AP10: =IF(C10="","",VLOOKUP(C10,$C$85:$T$110,12,FALSE)) | AS10: 남은 원금 | AV10: =IF(AV7="","",AV7-AV9) | BB10: =IFERROR(__xludf.DUMMYFUNCTION("IFERROR(SPARKLINE(BD9,{""charttype"", ""column"";""color"",""FF0000""; ""negcolor"", ""0000FF""; ""ymin"", -0.3 ; ""ymax"", +0.2 ;""axis"",true ; ""axiscolor"",""000000""}),"""")"),"") | BT10: =$J$8 -> 0.1 | BW10: =IF(O8>O23,IF(BY10<BY11,ROUNDDOWN(O23/2/BY10,0),""),IF(BY10<BY11,ROUNDDOWN(O8/2/BY10,0),"")) | BY10: =IF(AC8="","",AC8*(1+J8)) | CB10: =$J$8/2 -> 0.05 | CE10: =IF(Q19>=0.5,"",IF(CG10<CG11,ROUNDDOWN(O8/2/CG10,0),"")) | CG10: =IF(AC8="","",AC8*(1+J8/2)) | CJ10: =$J$8/2 -> 0.05 | CM10: =IF(Q19>=0.5,"",IF(CO10<CO11,ROUNDDOWN(O8/2/CO10,0),"")) | CO10: =IF(AC8="","",AC8*(1+J8/2)) | CR10: =IF(T19="",J8,(J8-T19*J8/20*(40/M8))) -> 0.1 | CU10: =IF(Z8="","",IF(CW10>CW11,"",IF(Q19<0.5,ROUNDDOWN(O8/2/CW10,0),IF(O23<O8,ROUNDDOWN(O23/CW10,0),ROUNDDOWN(O8/CW10,0))))) | CW10: =IF(AC8="","",AC8*(1+CR10))
B11: 5 | E11: V2.2 | J11: 0.1 | M11: 40 | O11: =IF(G11="","",G11/M11) | R11: =IFERROR(IF(G11="","",ROUNDDOWN(O11/AH11,0)),"") | AF11: =IF(C11="","",VLOOKUP(C11,$C$85:$T$110,17,FALSE)) | AH11: =IF(C11="","",VLOOKUP(C11,$C$85:$T$110,3,FALSE)) | AJ11: =IF(C11="","",VLOOKUP(C11,$C$85:$T$110,6,FALSE)) | AM11: =IF(C11="","",VLOOKUP(C11,$C$85:$T$110,9,FALSE)) | AP11: =IF(C11="","",VLOOKUP(C11,$C$85:$T$110,12,FALSE)) | AS11: 소진율 | AV11: =IF(AV10="","",AV9/AV7) | BT11: 큰수 | BW11: =IF(O8>O23,IF(BY10>BY11,ROUNDDOWN(O23/BY11,0),""),IF(BY10>BY11,IF(BY9>BY11,ROUNDDOWN(O8/BY11,0),ROUNDDOWN(O8/2/BY11,0)),"")) | BY11: =IF(AC8="","",AH8*(1+BG16)) | CB11: 큰수 | CE11: =IF(Z8="","",IF(Q19>=0.5,IF(O23<O8,ROUNDDOWN(O23/CG11,0)-CE9,ROUNDDOWN(O8/CG11,0)-CE9),IF(CG10>CG11,IF(CG9>CG11,ROUNDDOWN(O8/CG11,0),ROUNDDOWN(O8/2/CG11,0)),""))) | CG11: =IF(AC8="","",AH8*(1+BG16)) | CJ11: 큰수 | CM11: =IF(Z8="","",IF(Q19>=0.5,IF(O23<O8,ROUNDDOWN(O23/CO11,0)-CM9,ROUNDDOWN(O8/CO11,0)-CM9),IF(CO10>CO11,IF(CO9>CO11,ROUNDDOWN(O8/CO11,0),ROUNDDOWN(O8/2/CO11,0)),""))) | CO11: =IF(AC8="","",AH8*(1+BG16)) | CR11: 큰수 | CU11: =IF(Z8="","",IF(CW10<CW11,"",IF(O23<O8,ROUNDDOWN(O23/CW11,0),IF(CW9>CW11,ROUNDDOWN(O8/CW11,0),ROUNDDOWN(O8/2/CW11,0))))) | CW11: =IF(AC8="","",AH8*(1+BG16))
B12: 6 | E12: V2.2 | J12: 0.1 | M12: 40 | O12: =IF(G12="","",G12/M12) | R12: =IFERROR(IF(G12="","",ROUNDDOWN(O12/AH12,0)),"") | AF12: =IF(C12="","",VLOOKUP(C12,$C$85:$T$110,17,FALSE)) | AH12: =IF(C12="","",VLOOKUP(C12,$C$85:$T$110,3,FALSE)) | AJ12: =IF(C12="","",VLOOKUP(C12,$C$85:$T$110,6,FALSE)) | AM12: =IF(C12="","",VLOOKUP(C12,$C$85:$T$110,9,FALSE)) | AP12: =IF(C12="","",VLOOKUP(C12,$C$85:$T$110,12,FALSE)) | AS12: =IFERROR(__xludf.DUMMYFUNCTION("IFERROR(IF(AV11>=0.5,SPARKLINE(AV11,{""charttype"",""bar"";""max"",1;""color1"",""FFB400""}),SPARKLINE(AV11,{""charttype"",""bar"";""max"",1;""color1"",""80E12A""})),"""")"),"") | BR12: 매도 | CJ12: 0 | CM12: =IF(Z8="","",IF(Q19>=0.5,(ROUND(Z8/4,0)),"")) | CO12: =IF(AC8="","",AC8*(1+$AV$14)) | CR12: =IF(T19="","",(J8-T19*J8/20*(40/M8))) | CU12: =IF(Z8="","",ROUND(Z8/4,0)) | CW12: =IF(AC8="","",IF(AND(39*(M8/40)<T19,T19<=40*(M8/40)),"MOC",AC8*(1+$AV$14+CR12)))
B13: 7 | E13: V2.2 | J13: 0.1 | M13: 40 | O13: =IF(G13="","",G13/M13) | R13: =IFERROR(IF(G13="","",ROUNDDOWN(O13/AH13,0)),"") | AF13: =IF(C13="","",VLOOKUP(C13,$C$85:$T$110,17,FALSE)) | AH13: =IF(C13="","",VLOOKUP(C13,$C$85:$T$110,3,FALSE)) | AJ13: =IF(C13="","",VLOOKUP(C13,$C$85:$T$110,6,FALSE)) | AM13: =IF(C13="","",VLOOKUP(C13,$C$85:$T$110,9,FALSE)) | AP13: =IF(C13="","",VLOOKUP(C13,$C$85:$T$110,12,FALSE)) | AS13: 1일 매입액 | AV13: =SUM(O7:Q16) -> 0 | BB13: ↔원금 | BD13: =IFERROR(BB8/AV7,0) -> 0 | CB13: =$J$8/2 -> 0.05 | CE13: =IF(Z8="","",IF(Q19>=0.5,(ROUND(Z8/2,0)),"")) | CG13: =IF(AC8="","",AC8*(1+J8/2+$AV$14)) | CJ13: =$J$8/2 -> 0.05 | CM13: =IF(Z8="","",ROUND(Z8/4,0)) | CO13: =IF(AC8="","",AC8*(1+J8/2+$AV$14))
B14: 8 | E14: V2.2 | J14: 0.1 | M14: 40 | O14: =IF(G14="","",G14/M14) | R14: =IFERROR(IF(G14="","",ROUNDDOWN(O14/AH14,0)),"") | AF14: =IF(C14="","",VLOOKUP(C14,$C$85:$T$110,17,FALSE)) | AH14: =IF(C14="","",VLOOKUP(C14,$C$85:$T$110,3,FALSE)) | AJ14: =IF(C14="","",VLOOKUP(C14,$C$85:$T$110,6,FALSE)) | AM14: =IF(C14="","",VLOOKUP(C14,$C$85:$T$110,9,FALSE)) | AP14: =IF(C14="","",VLOOKUP(C14,$C$85:$T$110,12,FALSE)) | AS14: 매도수수료 | AV14: 0.0002 | BB14: =IFERROR(__xludf.DUMMYFUNCTION("IFERROR(SPARKLINE(BD13,{""charttype"", ""column"";""color"",""FF0000""; ""negcolor"", ""0000FF""; ""ymin"", -0.3 ; ""ymax"", +0.2 ;""axis"",true ; ""axiscolor"",""000000""}),"""")"),"") | BT14: =$J$8 -> 0.1 | BW14: =IF(Z8="","",Z8) | BY14: =IF(AC8="","",AC8*(1+J8+$AV$14)) | CB14: =$J$8 -> 0.1 | CE14: =IF(CE13="",Z8,Z8-CE13) | CG14: =IF(AC8="","",AC8*(1+J8+$AV$14)) | CJ14: =$J$8 -> 0.1 | CM14: =IF(Z8="","",IF(Q19<0.5,Z8-CM13,Z8-CM12-CM13)) | CO14: =IF(AC8="","",AC8*(1+J8+$AV$14)) | CR14: =$J$8 -> 0.1 | CU14: =IF(Z8="","",Z8-CU12) | CW14: =IF(AC8="","",AC8*(1+J8+$AV$14))
B15: 9 | E15: V2.2 | J15: 0.1 | M15: 40 | O15: =IF(G15="","",G15/M15) | R15: =IFERROR(IF(G15="","",ROUNDDOWN(O15/AH15,0)),"") | AF15: =IF(C15="","",VLOOKUP(C15,$C$85:$T$110,17,FALSE)) | AH15: =IF(C15="","",VLOOKUP(C15,$C$85:$T$110,3,FALSE)) | AJ15: =IF(C15="","",VLOOKUP(C15,$C$85:$T$110,6,FALSE)) | AM15: =IF(C15="","",VLOOKUP(C15,$C$85:$T$110,9,FALSE)) | AP15: =IF(C15="","",VLOOKUP(C15,$C$85:$T$110,12,FALSE)) | AS15: 증액가능 | AV15: =COUNTA(C7:C16)*2/100 -> 0 | BG15: 큰수 기준 | BP15: 3 | BR15: 매수 | BT15: 평단 | BW15: =IF(BY15>BY17,"",IF(Y23<O9,IF(BY16<BY17,ROUNDDOWN(Y23/BY15-BW16,0),ROUNDDOWN(Y23/BY15-BW17,0)),IF(AC9="","",IF(BY16<BY17,ROUNDDOWN(O9/BY15-BW16,0),ROUNDDOWN(O9/BY15-BW17,0))))) | BY15: =IF(AC9="","",AC9) | CB15: 평단 | CE15: =IF(Z9="","",IF(CG15>CG17,"",IF(AA19>=0.5,IF(O9>Y23,ROUNDDOWN(Y23/CG15,0),ROUNDDOWN(O9/CG15,0)),IF(AC9="","",IF(CG16<CG17,ROUNDDOWN(O9/CG15,0)-CE16,ROUNDDOWN(O9/CG15,0)-CE17))))) | CG15: =IF(AC9="","",AC9) | CJ15: 평단 | CM15: =IF(Z9="","",IF(CO15>CO17,"",IF(AA19>=0.5,IF(O9>Y23,ROUNDDOWN(Y23/CO15,0),ROUNDDOWN(O9/CO15,0)),IF(AC9="","",IF(CO16<CO17,ROUNDDOWN(O9/CO15,0)-CM16,ROUNDDOWN(O9/CO15,0)-CM17))))) | CO15: =IF(AC9="","",AC9) | CR15: 평단 | CU15: =IF(CW15>CW17,"",IF(AA19<0.5,IF(AC9="","",IF(CW16<CW17,ROUNDDOWN(O9/CW15,0)-CU16,ROUNDDOWN(O9/CW15,0)-CU17)),"")) | CW15: =IF(AC9="","",AC9)
B16: 10 | E16: V2.2 | J16: 0.1 | M16: 40 | O16: =IF(G16="","",G16/M16) | R16: =IFERROR(IF(G16="","",ROUNDDOWN(O16/AH16,0)),"") | AF16: =IF(C16="","",VLOOKUP(C16,$C$85:$T$110,17,FALSE)) | AH16: =IF(C16="","",VLOOKUP(C16,$C$85:$T$110,3,FALSE)) | AJ16: =IF(C16="","",VLOOKUP(C16,$C$85:$T$110,6,FALSE)) | AM16: =IF(C16="","",VLOOKUP(C16,$C$85:$T$110,9,FALSE)) | AP16: =IF(C16="","",VLOOKUP(C16,$C$85:$T$110,12,FALSE)) | AS16: TODAY | AV16: =TODAY() -> 46224 | BG16: 0.15 | BT16: =$J$9 -> 0.1 | BW16: =IF(O9>Y23,IF(BY16<BY17,ROUNDDOWN(Y23/2/BY16,0),""),IF(BY16<BY17,ROUNDDOWN(O9/2/BY16,0),"")) | BY16: =IF(AC9="","",AC9*(1+J9)) | CB16: =$J$9/2 -> 0.05 | CE16: =IF(AA19>=0.5,"",IF(CG16<CG17,ROUNDDOWN(O9/2/CG16,0),"")) | CG16: =IF(AC9="","",AC9*(1+J9/2)) | CJ16: =$J$9/2 -> 0.05 | CM16: =IF(AA19>=0.5,"",IF(CO16<CO17,ROUNDDOWN(O9/2/CO16,0),"")) | CO16: =IF(AC9="","",AC9*(1+J9/2)) | CR16: =IF(AD19="",J9,(J9-AD19*J9/20*(40/M9))) -> 0.1 | CU16: =IF(Z9="","",IF(CW16>CW17,"",IF(AA19<0.5,ROUNDDOWN(O9/2/CW16,0),IF(Y23<O9,ROUNDDOWN(Y23/CW16,0),ROUNDDOWN(O9/CW16,0))))) | CW16: =IF(AC9="","",AC9*(1+CR16))
BT17: 큰수 | BW17: =IF(O9>Y23,IF(BY16>BY17,ROUNDDOWN(Y23/BY17,0),""),IF(BY16>BY17,IF(BY15>BY17,ROUNDDOWN(O9/BY17,0),ROUNDDOWN(O9/2/BY17,0)),"")) | BY17: =IF(AC9="","",AH9*(1+BG16)) | CB17: 큰수 | CE17: =IF(Z9="","",IF(AA19>=0.5,IF(Y23<O9,ROUNDDOWN(Y23/CG17,0)-CE15,ROUNDDOWN(O9/CG17,0)-CE15),IF(CG16>CG17,IF(CG15>CG17,ROUNDDOWN(O9/CG17,0),ROUNDDOWN(O9/2/CG17,0)),""))) | CG17: =IF(AC9="","",AH9*(1+BG16)) | CJ17: 큰수 | CM17: =IF(Z9="","",IF(AA19>=0.5,IF(Y23<O9,ROUNDDOWN(Y23/CO17,0)-CM15,ROUNDDOWN(O9/CO17,0)-CM15),IF(CO16>CO17,IF(CO15>CO17,ROUNDDOWN(O9/CO17,0),ROUNDDOWN(O9/2/CO17,0)),""))) | CO17: =IF(AC9="","",AH9*(1+BG16)) | CR17: 큰수 | CU17: =IF(Z9="","",IF(CW16<CW17,"",IF(Y23<O9,ROUNDDOWN(Y23/CW17,0),IF(CW15>CW17,ROUNDDOWN(O9/CW17,0),ROUNDDOWN(O9/2/CW17,0))))) | CW17: =IF(AC9="","",AH9*(1+BG16))
B18: 1 | C18: =IF(C7="","",C7) | J18: =IF(E7="","",E7) -> V2.2 | L18: 2 | M18: =IF(C8="","",C8) | T18: =IF(E8="","",E8) -> V2.2 | V18: 3 | W18: =IF(C9="","",C9) | AD18: =IF(E9="","",E9) -> V2.2 | AF18: 4 | AG18: =IF(C10="","",C10) | AN18: =IF(E10="","",E10) -> V2.2 | AP18: 5 | AQ18: =IF(C11="","",C11) | AX18: =IF(E11="","",E11) -> V2.2 | BA18: * 초록색은 LOC 매도 , 파란색은 지정가 매도 | BR18: 매도 | CJ18: 0 | CM18: =IF(Z9="","",IF(AA19>=0.5,(ROUND(Z9/4,0)),"")) | CO18: =IF(AC9="","",AC9*(1+$AV$14)) | CR18: =IF(AD19="","",(J9-AD19*J9/20*(40/M9))) | CU18: =IF(Z9="","",ROUND(Z9/4,0)) | CW18: =IF(AC9="","",IF(AND(39*(M9/40)<AD19,AD19<=40*(M9/40)),"MOC",AC9*(1+$AV$14+CR18)))
